File: example_data/S2-IP-MH@5K_2T_course_8kOe_fine.dat
[Header]
; MPMS3 Data File (default extension .dat)
; Copyright (c) 2007, Quantum Design, Inc. All rights reserved.
TITLE,
FILEOPENTIME,3856105939.60934,03/10/2022,8:31 pm
BYAPP,MPMS3 w/ AC,1.0,1.1
INFO,MPMS3 Measurement Release 1.1.16 Build 424, MultiVu Release 2.3.4.19,APPNAME
INFO,Linear Motor Servo Controller,MOTOR_MODULE_NAME
INFO,3101-100 M0,MOTOR_HW_VERSION
INFO,MMC901,MOTOR_SERIAL_NUMBER
INFO,01.04.28,MOTOR_SOFTWARE_VERSION
INFO,Quantum Design Squid Module,SQUID_MODULE_NAME
INFO,3101-501 B0,SQUID_HW_VERSION
INFO,SQM233,SQUID_SERIAL_NUMBER
INFO,01.03.04,SQUID_SOFTWARE_VERSION
INFO,Quantum Design VSM Oven,OVEN_MODULE_NAME
INFO,3101-201 A3,OVEN_HW_VERSION
INFO,OVB284,OVEN_SERIAL_NUMBER
INFO,01.07.07,OVEN_SOFTWARE_VERSION
INFO,SQUID AC,AC_MODULE_NAME
INFO,3101-401 F2,AC_HW_VERSION
INFO,SAC147,AC_SERIAL_NUMBER
INFO,SQUID AC 00.95.07,AC_SOFTWARE_VERSION
INFO,TCI231-2,COIL_SERIAL_NUMBER
INFO,0,MOMENT_UNITS
INFO,S1,SAMPLE_MATERIAL
INFO,,SAMPLE_COMMENT
INFO,,SAMPLE_MASS
INFO,,SAMPLE_VOLUME
INFO,,SAMPLE_MOLECULAR_WEIGHT
INFO,,SAMPLE_SIZE
INFO,,SAMPLE_SHAPE
INFO,Straw,SAMPLE_HOLDER
INFO,Standard,SAMPLE_HOLDER_DETAIL
INFO,65.32,SAMPLE_OFFSET
DATATYPE,COMMENT,1
DATATYPE,TIME,2
STARTUPAXIS,X,2
STARTUPAXIS,Y1,5
FIELDGROUP, VSM,2,3,4,5,6,8,9,10,11,14,15
FIELDGROUP, DC, 2,3,4,14,56,57,58,59,60,61,62,63,64,65,66,67,68,69
FIELDGROUP, AC, 2,3,4,11,16,17,18,19,20,21,22,23,24,25,26,27,28,29,30
STARTUPGROUP, All
[Data]
Comment,Time Stamp (sec),Temperature (K),Magnetic Field (Oe),Moment (emu),M. Std. Err. (emu),Transport Action,Averaging Time (sec),Frequency (Hz),Peak Amplitude (mm),Center Position (mm),Lockin Signal' (V),Lockin Signal (V),Range,M. Quad. Signal (emu),AC Moment (emu),AC M. Std Err. (emu),AC Phase (deg),AC Phase Std. Err. (deg),AC Susceptibility (emu/Oe),AC Suscept. Std Err. (emu/Oe),AC X' (emu/Oe),AC X' Std Err. (emu/Oe),AC X'' (emu/Oe),AC X'' Std Err. (emu/Oe),AC Drive (Oe),AC Frequency (Hz),AC Averaging Time (sec),AC Cycles,AC Range,AC Measure Type,AC Signal' (V),AC Signal'' (V),AC Trim Coil Ratio,AC Trim Coil Phase,Min. Temperature (K),Max. Temperature (K),Min. Field (Oe),Max. Field (Oe),Mass (grams),Motor Lag (deg),Pressure (Torr),Measure Count,Measurement Number,SQUID Status (code),Motor Status (code),Measure Status (code),Motor Current (amps),Motor Temp. (C),Temp. Status (code),Field Status (code),Chamber Status (code),Chamber Temp (K),Redirection State,Average Temp (K),Rotation Angle (deg),Rotator state,DC Moment Fixed Ctr (emu),DC Moment Err Fixed Ctr (emu),DC Moment Free Ctr (emu),DC Moment Err Free Ctr (emu),DC Fixed Fit,DC Free Fit,DC Calculated Center (mm),DC Calculated Center Err (mm),DC Scan Length (mm),DC Scan Time (s),DC Number of Points,DC Squid Drift,DC Min V (V),DC Max V (V),DC Scans per Measure,Map 01,Map 02,Map 03,Map 04,Map 05,Map 06,Map 07,Map 08,Map 09,Map 10,Map 11,Map 12,Map 13,Map 14,Map 15,Map 16
,3856106012.7761,5.00054740905762,0.012241767719388,2.49974428105469E-6,8.42484173776715E-9,1,2,14.0008964538574,4.98628250276451,32.8399986028671,0.00301429769215465,0.000445936757200716,1,-1.32765372943888E-8,,,,,,,,,,,,,,,,,,,,,5.00054740905762,5.00054740905762,0.012241767719388,0.012241767719388,54.5252330587654,5.83335408454824,3.21321725845337,28,1,0,0,1,0.321197509765625,28.8367557525635,1,1,1,5.00054740905762,0,5.00054740905762,,,,,,,,,,,,,,,,,,,,,,,,,,,,,,,,,
,3856106037.27701,5.00172114372253,1149.64892578125,1.54343016507386E-6,2.20428934463345E-8,1,2,14.0008964538574,4.98596089981453,32.8399986028671,0.00182599565446328,0.000503318286467826,1,1.81058207474491E-7,,,,,,,,,,,,,,,,,,,,,4.99811363220215,5.00532865524292,1149.64892578125,1149.64892578125,54.7632389428712,5.83723685588349,3.20464420318604,28,1,0,0,1,0.31982421875,28.8367557525635,1,1,1,4.99811363220215,0,5.00172114372253,,,,,,,,,,,,,,,,,,,,,,,,,,,,,,,,,
,3856106064.59579,4.99245977401733,2599.66186523438,-5.56377583654248E-6,1.57302753772815E-8,1,2,14.0008964538574,4.98595567343195,32.8399986028671,-0.00674415158368041,-0.000759481000812152,1,2.22923161168186E-7,,,,,,,,,,,,,,,,,,,,,4.99199962615967,4.992919921875,2599.66186523438,2599.66186523438,54.5998785823519,5.83842723929167,3.19663643836975,28,1,0,0,1,0.323715209960937,28.8367557525635,1,1,1,4.99199962615967,0,4.99245977401733,,,,,,,,,,,,,,,,,,,,,,,,,,,,,,,,,
,3856106109.67237,4.99899482727051,4049.68725585937,-1.77545825362564E-5,1.06326156383461E-8,1,2,14.0008964538574,4.98651082742991,32.8399986028671,-0.0214102416087742,-0.00316984344555296,1,9.23487735523011E-8,,,,,,,,,,,,,,,,,,,,,4.99899482727051,4.99899482727051,4049.68725585937,4049.68725585937,54.6456038507269,5.83466669770314,3.17852544784546,28,1,0,0,1,0.320663452148438,28.8367557525635,1,1,1,4.99899482727051,0,4.99899482727051,,,,,,,,,,,,,,,,,,,,,,,,,,,,,,,,,
,3856106136.94489,5.00270414352417,5499.7001953125,-3.20101456023563E-5,1.36895955544538E-8,1,2,14.0008964538574,4.98668616547134,32.8399986028671,-0.0386124940095711,-0.00565283090025401,1,2.18310487716169E-7,,,,,,,,,,,,,,,,,,,,,5.00213861465454,5.0032696723938,5499.7001953125,5499.7001953125,54.6581099070346,5.83686544801769,3.17124652862549,28,1,0,0,1,0.32012939453125,28.8367557525635,1,1,1,5.00213861465454,0,5.00270414352417,,,,,,,,,,,,,,,,,,,,,,,,,,,,,,,,,
,3856106165.05247,4.99966192245483,6949.5166015625,-4.69053952440017E-5,1.79888998003684E-8,1,2,14.0008964538574,4.98581553799598,32.8399986028671,-0.056559677366607,-0.00832358861993936,1,2.84737167802483E-7,,,,,,,,,,,,,,,,,,,,,4.99944019317627,4.9998836517334,6949.5166015625,6949.5166015625,54.5404748148904,5.84357691698363,3.17230248451233,28,1,0,0,1,0.320510864257812,26.881721496582,1,1,1,4.99944019317627,0,4.99966192245483,,,,,,,,,,,,,,,,,,,,,,,,,,,,,,,,,
,3856106192.8658,5.00008201599121,8399.73828125,-6.20768449159633E-5,2.0281177924611E-8,1,2,14.0008964538574,4.98638260834803,32.8399986028671,-0.074848898483297,-0.0111271894573494,1,2.85873227110683E-7,,,,,,,,,,,,,,,,,,,,,5.00000810623169,5.00015592575073,8399.73828125,8399.73828125,54.5088188598615,5.83722614534883,3.16831612586975,28,1,0,0,1,0.3204345703125,28.3479976654053,1,1,1,5.00000810623169,0,5.00008201599121,,,,,,,,,,,,,,,,,,,,,,,,,,,,,,,,,
,3856106220.17785,5.00028991699219,9849.580078125,-7.74865492770762E-5,2.57142672697013E-8,1,2,14.0008964538574,4.98622772603312,32.8399986028671,-0.0934233127595334,-0.0138998942692302,1,3.47590717059978E-7,,,,,,,,,,,,,,,,,,,,,5.00023984909058,5.0003399848938,9849.580078125,9849.580078125,54.7866877984481,5.8374886429945,3.15475988388062,28,1,0,0,1,0.322647094726562,29.3255138397217,1,1,1,5.00023984909058,0,5.00028991699219,,,,,,,,,,,,,,,,,,,,,,,,,,,,,,,,,
,3856106249.40403,5.0002224445343,11299.8740234375,-9.29020025682427E-5,2.6939954027748E-8,1,2,14.0008964538574,4.98605909645526,32.8399986028671,-0.111993072058616,-0.0167355071694856,1,3.57721034082364E-7,,,,,,,,,,,,,,,,,,,,,5.00004577636719,5.00039911270142,11299.8740234375,11299.8740234375,54.7206401885731,5.83949200180181,3.15044379234314,28,1,0,0,1,0.322265625,29.3255138397217,1,1,1,5.00039911270142,0,5.0002224445343,,,,,,,,,,,,,,,,,,,,,,,,,,,,,,,,,
,3856106277.75163,4.99970078468323,12749.6298828125,-0.000108341447235971,4.86840469396752E-8,1,2,14.0008964538574,4.98593586739411,32.8399986028671,-0.130585787450418,-0.0196136946432826,1,3.36175987260731E-7,,,,,,,,,,,,,,,,,,,,,4.99853372573853,5.00086784362793,12749.6298828125,12749.6298828125,54.5842460119673,5.8425024502493,3.15307950973511,28,1,0,0,1,0.320663452148438,29.3255138397217,1,1,1,5.00086784362793,0,4.99970078468323,,,,,,,,,,,,,,,,,,,,,,,,,,,,,,,,,
,3856106305.65918,4.99912047386169,14199.740234375,-0.000124285141714113,3.47973539516152E-8,1,2,14.0008964538574,4.98601713855372,32.8399986028671,-0.149822395391551,-0.0223963851529719,1,4.7214153088561E-7,,,,,,,,,,,,,,,,,,,,,4.99836349487305,4.99987745285034,14199.740234375,14199.740234375,54.9410594309962,5.83887070700256,3.14107990264893,28,1,0,0,1,0.321273803710937,28.8367557525635,1,1,1,4.99987745285034,0,4.99912047386169,,,,,,,,,,,,,,,,,,,,,,,,,,,,,,,,,
,3856106333.67423,4.99964141845703,15649.6552734375,-0.000139898042329704,3.76299267774676E-8,1,2,14.0008964538574,4.98592480141646,32.8399986028671,-0.168618434025101,-0.0253429865635973,1,4.20403725400782E-7,,,,,,,,,,,,,,,,,,,,,4.99952268600464,4.99976015090942,15649.6552734375,15649.6552734375,54.5181984020923,5.83678904062397,3.1377739906311,28,1,0,0,1,0.321426391601562,28.8367557525635,1,1,1,4.99952268600464,0,4.99964141845703,,,,,,,,,,,,,,,,,,,,,,,,,,,,,,,,,
,3856106362.20877,4.99959325790405,17099.681640625,-0.000155512243206739,3.60729040227475E-8,1,2,14.0008964538574,4.98619865998073,32.8399986028671,-0.187437202353563,-0.0282739426436525,1,3.84139294369891E-7,,,,,,,,,,,,,,,,,,,,,4.99937963485718,4.99980688095093,17099.681640625,17099.681640625,54.8527354083231,5.83826221738041,3.14078283309937,28,1,0,0,1,0.322113037109375,29.3255138397217,1,1,1,4.99937963485718,0,4.99959325790405,,,,,,,,,,,,,,,,,,,,,,,,,,,,,,,,,
,3856106390.35771,4.99979138374329,18549.767578125,-0.000171126536317284,3.86678341326527E-8,1,2,14.0008964538574,4.98558692596615,32.8399986028671,-0.206212965810046,-0.0311630870759227,1,3.76529021706805E-7,,,,,,,,,,,,,,,,,,,,,4.99945163726807,5.00013113021851,18549.767578125,18549.767578125,54.850781337025,5.84018812261709,3.1402530670166,28,1,0,0,1,0.324172973632812,28.8367557525635,1,1,1,5.00013113021851,0,4.99979138374329,,,,,,,,,,,,,,,,,,,,,,,,,,,,,,,,,
,3856106418.24582,4.99972558021545,19999.62109375,-0.00018668400840377,3.99712869306691E-8,1,2,14.0008964538574,4.98530214772464,32.8500010073185,-0.224941486831778,-0.0339982502272673,1,4.06790424605592E-7,,,,,,,,,,,,,,,,,,,,,4.99958515167236,4.99986600875854,19999.62109375,19999.62109375,54.3947010960538,5.84777053286538,3.12938499450684,28,1,0,0,1,0.321121215820313,28.3479976654053,1,1,1,4.99986600875854,0,4.99972558021545,,,,,,,,,,,,,,,,,,,,,,,,,,,,,,,,,
,3856106450.39396,4.9979932308197,19274.76171875,-0.000178778417646825,4.3585406302819E-8,1,2,14.0008964538574,4.98488086770414,32.8399986028671,-0.215384249453921,-0.0325940466472781,1,3.56858924349306E-7,,,,,,,,,,,,,,,,,,,,,4.99774599075317,4.99824047088623,19274.76171875,19274.76171875,54.7546410291596,5.84858325099225,3.12835359573364,28,1,0,0,1,0.321044921875,29.3255138397217,1,1,1,4.99824047088623,0,4.9979932308197,,,,,,,,,,,,,,,,,,,,,,,,,,,,,,,,,
,3856106479.61392,4.99945664405823,17824.56640625,-0.000162935627032346,4.1160302328184E-8,1,2,14.0008964538574,4.98514317730286,32.8399986028671,-0.196281744578257,-0.0299053346597228,1,1.61278358195439E-7,,,,,,,,,,,,,,,,,,,,,4.99931764602661,4.99959564208984,17824.56640625,17824.56640625,54.5944071827173,5.84579878483443,3.12287211418152,28,1,0,0,1,0.321884155273438,29.3255138397217,1,1,1,4.99959564208984,0,4.99945664405823,,,,,,,,,,,,,,,,,,,,,,,,,,,,,,,,,
,3856106506.91132,5.00004363059998,16374.69921875,-0.000147352530448468,4.38698063610338E-8,1,2,14.0008964538574,4.98554504903295,32.8500010073185,-0.177519634837614,-0.0271124676820495,1,9.25477496404613E-8,,,,,,,,,,,,,,,,,,,,,4.99982500076294,5.00026226043701,16374.69921875,16374.69921875,54.5279687585827,5.84361412245255,3.11780762672424,28,1,0,0,1,0.32470703125,28.8367557525635,1,1,1,4.99982500076294,0,5.00004363059998,,,,,,,,,,,,,,,,,,,,,,,,,,,,,,,,,
,3856106535.20206,5.00010657310486,14924.6494140625,-0.000131636137471354,2.61267136099154E-8,1,2,14.0008964538574,4.98553781259437,32.8399986028671,-0.158589990767709,-0.0241903391125152,1,1.07834674588201E-7,,,,,,,,,,,,,,,,,,,,,4.99997329711914,5.00023984909058,14924.6494140625,14924.6494140625,54.7417441585923,5.8429629761443,3.11308026313782,28,1,0,0,1,0.321197509765625,29.3255138397217,1,1,1,5.00023984909058,0,5.00010657310486,,,,,,,,,,,,,,,,,,,,,,,,,,,,,,,,,
,3856106562.88398,4.99957299232483,13474.673828125,-0.000115941915304759,2.92970400514854E-8,1,2,14.0008964538574,4.98535016546511,32.8399986028671,-0.139664443490092,-0.0213729992845187,1,3.86424631728742E-8,,,,,,,,,,,,,,,,,,,,,4.99944877624512,4.99969720840454,13474.673828125,13474.673828125,54.5260146872846,5.84568192945003,3.11174607276916,28,1,0,0,1,0.322341918945313,29.3255138397217,1,1,1,4.99944877624512,0,4.99957299232483,,,,,,,,,,,,,,,,,,,,,,,,,,,,,,,,,
,3856106589.88811,5.00039291381836,12024.708984375,-0.000100322463718178,3.35057352315623E-8,1,2,14.0008964538574,4.98560427560032,32.8399986028671,-0.12086376700447,-0.0184558985013726,1,6.58909867033007E-8,,,,,,,,,,,,,,,,,,,,,5.00025701522827,5.00052881240845,12024.708984375,12024.708984375,54.6381783797942,5.84046794282747,3.10984587669373,28,1,0,0,1,0.322494506835937,29.3255138397217,1,1,1,5.00052881240845,0,5.00039291381836,,,,,,,,,,,,,,,,,,,,,,,,,,,,,,,,,
,3856106618.10355,5.00050187110901,10574.732421875,-8.47842013460174E-5,2.77522030793445E-8,1,2,14.0008964538574,4.98571633625301,32.8399986028671,-0.102136842240557,-0.0156655318706711,1,-4.71409993543237E-10,,,,,,,,,,,,,,,,,,,,,4.99987125396729,5.00113248825073,10574.732421875,10574.732421875,54.6260631377462,5.84077964014502,3.10359406471252,28,1,0,0,1,0.323715209960937,28.8367557525635,1,1,1,5.00113248825073,0,5.00050187110901,,,,,,,,,,,,,,,,,,,,,,,,,,,,,,,,,
,3856106644.94428,5.00012040138245,9124.6337890625,-6.92982573858253E-5,2.71669034089872E-8,1,2,14.0008964538574,4.98538894612612,32.8399986028671,-0.0834798275594708,-0.0127633186248114,1,3.25777511247491E-8,,,,,,,,,,,,,,,,,,,,,4.99995946884155,5.00028133392334,9124.6337890625,9124.6337890625,54.6631904924096,5.84460064256934,3.10497117042542,28,1,0,0,1,0.323257446289063,29.3255138397217,1,1,1,5.00028133392334,0,5.00012040138245,,,,,,,,,,,,,,,,,,,,,,,,,,,,,,,,,
,3856106671.36945,4.9996542930603,7999.689453125,-5.73629836281258E-5,2.54103189446221E-8,1,2,14.0008964538574,4.98560493505016,32.8399986028671,-0.0691123387143651,-0.010526016699396,1,5.99315272308302E-8,,,,,,,,,,,,,,,,,,,,,4.99938869476318,4.99991989135742,7999.689453125,7999.689453125,54.7862969841885,5.84285718286705,3.09707522392273,28,1,0,0,1,0.320358276367188,29.8142719268799,1,1,1,4.99938869476318,0,4.9996542930603,,,,,,,,,,,,,,,,,,,,,,,,,,,,,,,,,
,3856106700.91724,5.00088214874268,7703.40185546875,-5.41573943796189E-5,1.58875378711392E-8,1,2,14.0008964538574,4.98550893521167,32.8399986028671,-0.0652514091505276,-0.00991794618268372,1,7.28383781204684E-8,,,,,,,,,,,,,,,,,,,,,5.00050783157349,5.00125646591186,7703.40185546875,7703.40185546875,54.6897658620635,5.84311124250908,3.0956883430481,28,1,0,0,1,0.322418212890625,27.8592376708984,1,1,1,5.00125646591186,0,5.00088214874268,,,,,,,,,,,,,,,,,,,,,,,,,,,,,,,,,
,3856106723.89036,4.99970769882202,7110.60595703125,-4.79839509131105E-5,1.95386752033603E-8,1,2,14.0008964538574,4.98549461726214,32.8399986028671,-0.0578123976166602,-0.00879205181785534,1,6.06375852475237E-8,,,,,,,,,,,,,,,,,,,,,4.99942398071289,4.99999141693115,7110.60595703125,7110.60595703125,54.7558134719385,5.84354880674871,3.10248899459839,28,1,0,0,1,0.321044921875,28.8367557525635,1,1,1,4.99942398071289,0,4.99970769882202,,,,,,,,,,,,,,,,,,,,,,,,,,,,,,,,,
,3856106751.26502,5.00008296966553,6518.75341796875,-4.17740662149209E-5,1.8033042453909E-8,1,2,14.0008964538574,4.98550679012963,32.8399986028671,-0.0503285409469127,-0.00766850726711487,1,4.09519032975272E-8,,,,,,,,,,,,,,,,,,,,,5.00002288818359,5.00014305114746,6518.75341796875,6518.75341796875,54.7460431154481,5.84184746427524,3.0870954990387,28,1,0,0,1,0.320587158203125,28.8367557525635,1,1,1,5.00014305114746,0,5.00008296966553,,,,,,,,,,,,,,,,,,,,,,,,,,,,,,,,,
,3856106773.57772,4.99953365325928,5925.71337890625,-3.5550635390178E-5,1.56730591847314E-8,1,2,14.0008964538574,4.98555450714053,32.8500010073185,-0.0428185410601192,-0.00660903572343845,1,-3.3953132748104E-8,,,,,,,,,,,,,,,,,,,,,4.99952936172485,4.9995379447937,5925.71337890625,5925.71337890625,54.5752572839962,5.84419173080996,3.08630204200745,28,1,0,0,1,0.32135009765625,28.8367557525635,1,1,1,4.9995379447937,0,4.99953365325928,,,,,,,,,,,,,,,,,,,,,,,,,,,,,,,,,
,3856106796.63166,4.99982404708862,5333.08935546875,-2.95198023783345E-5,1.57486391153497E-8,1,2,14.0008964538574,4.98566811528401,32.8399986028671,-0.0355562767508428,-0.00548566247848,1,-2.62115953790836E-8,,,,,,,,,,,,,,,,,,,,,4.99976921081543,4.99987888336182,5333.08935546875,5333.08935546875,54.4767720905731,5.84166259722802,3.08006954193115,28,1,0,0,1,0.322952270507812,29.8142719268799,1,1,1,4.99976921081543,0,4.99982404708862,,,,,,,,,,,,,,,,,,,,,,,,,,,,,,,,,
,3856106819.6957,4.99995708465576,4740.63720703125,-2.35273539670613E-5,1.65898409079932E-8,1,2,14.0008964538574,4.98544249347385,32.8399986028671,-0.0283338097697967,-0.00439027816109424,1,-3.62230725049718E-8,,,,,,,,,,,,,,,,,,,,,4.99987268447876,5.00004148483276,4740.63720703125,4740.63720703125,54.7648021999096,5.84323965277342,3.07684731483459,28,1,0,0,1,0.320892333984375,29.3255138397217,1,1,1,4.99987268447876,0,4.99995708465576,,,,,,,,,,,,,,,,,,,,,,,,,,,,,,,,,
,3856106842.959,4.99987816810608,4147.84130859375,-1.76657259408663E-5,1.58555546941525E-8,1,2,14.0008964538574,4.98534499690242,32.8399986028671,-0.0212693109511782,-0.00332770506741331,1,-5.31961574250004E-8,,,,,,,,,,,,,,,,,,,,,4.99983930587769,4.99991703033447,4147.84130859375,4147.84130859375,54.5166351450538,5.84526314034365,3.0689754486084,28,1,0,0,1,0.322647094726562,29.3255138397217,1,1,1,4.99991703033447,0,4.99987816810608,,,,,,,,,,,,,,,,,,,,,,,,,,,,,,,,,
,3856106866.12849,4.99949431419373,3555.59692382812,-1.19720201536542E-5,1.23469655629115E-8,1,2,14.0008964538574,4.98561898540902,32.8399986028671,-0.0144095794432552,-0.0022924588789816,1,-6.68548249272822E-8,,,,,,,,,,,,,,,,,,,,,4.99930906295776,4.99967956542969,3555.59692382812,3555.59692382812,54.4869332613231,5.8433584614205,3.07690167427063,28,1,0,0,1,0.322113037109375,29.3255138397217,1,1,1,4.99967956542969,0,4.99949431419373,,,,,,,,,,,,,,,,,,,,,,,,,,,,,,,,,
,3856106889.30715,4.99969434738159,2962.88745117188,-6.50020292308214E-6,1.27034975174376E-8,1,2,14.0008964538574,4.98572032638286,32.8399986028671,-0.00781701004435529,-0.00128963098344095,1,-7.35754032301589E-8,,,,,,,,,,,,,,,,,,,,,4.99945688247681,4.99993181228638,2962.88745117188,2962.88745117188,54.7014902898519,5.84101249915226,3.06982898712158,28,1,0,0,1,0.321273803710937,28.8367557525635,1,1,1,4.99993181228638,0,4.99969434738159,,,,,,,,,,,,,,,,,,,,,,,,,,,,,,,,,
,3856106913.07944,4.99998927116394,2370.5693359375,-1.3528952025883E-6,1.10790235601447E-8,1,2,14.0008964538574,4.98581007942528,32.8399986028671,-0.00161591933555322,-0.000340698127150806,1,-7.53106966563563E-8,,,,,,,,,,,,,,,,,,,,,4.99979257583618,5.0001859664917,2370.5693359375,2370.5693359375,54.5885449688231,5.84194116953536,3.07428932189941,28,1,0,0,1,0.322113037109375,29.8142719268799,1,1,1,5.0001859664917,0,4.99998927116394,,,,,,,,,,,,,,,,,,,,,,,,,,,,,,,,,
,3856106937.11995,5.00001740455627,1778.05554199219,3.33920356575182E-6,1.08946581751848E-8,1,2,14.0008964538574,4.98573706026636,32.8399986028671,0.00403743253073221,0.00052064351618469,1,-7.99555646855647E-8,,,,,,,,,,,,,,,,,,,,,4.99997854232788,5.00005626678467,1778.05554199219,1778.05554199219,54.5400840006308,5.84251520749332,3.07331228256226,28,1,0,0,1,0.3216552734375,29.3255138397217,1,1,1,5.00005626678467,0,5.00001740455627,,,,,,,,,,,,,,,,,,,,,,,,,,,,,,,,,
,3856106961.55738,4.99937987327576,1184.9296875,7.32711756855288E-6,9.44945914095544E-9,1,2,14.0008964538574,4.98571541661777,32.8399986028671,0.00884198271663466,0.0012544708448677,1,-8.2435380155125E-8,,,,,,,,,,,,,,,,,,,,,4.99932718276978,4.99943256378174,1184.9296875,1184.9296875,54.5951888112365,5.84083787093603,3.07401394844055,28,1,0,0,1,0.32257080078125,28.8367557525635,1,1,1,4.99943256378174,0,4.99937987327576,,,,,,,,,,,,,,,,,,,,,,,,,,,,,,,,,
,3856106985.76677,4.99998474121094,592.158813476563,9.73604631231918E-6,9.92066446256281E-9,1,2,14.0008964538574,4.98597290058566,32.8399986028671,0.0117423678120243,0.00171549361183968,1,-6.93044275848773E-8,,,,,,,,,,,,,,,,,,,,,4.99968528747559,5.00028419494629,592.158813476563,592.158813476563,54.5502451713808,5.8396628438954,3.07019758224487,28,1,0,0,1,0.324325561523438,29.3255138397217,1,1,1,5.00028419494629,0,4.99998474121094,,,,,,,,,,,,,,,,,,,,,,,,,,,,,,,,,
,3856107010.67546,4.99976348876953,-0.232593595981598,1.1021984099633E-5,1.49319006013601E-8,1,2,14.0008964538574,4.98603673276516,32.8399986028671,0.0132928264573358,0.00194675722375862,1,-7.46016386176427E-8,,,,,,,,,,,,,,,,,,,,,4.99961090087891,4.99991607666016,-0.232593595981598,-0.232593595981598,54.5475094715635,5.8398336196806,3.06473803520203,28,1,0,0,1,0.322341918945313,29.3255138397217,1,1,1,4.99991607666016,0,4.99976348876953,,,,,,,,,,,,,,,,,,,,,,,,,,,,,,,,,
,3856107034.10412,5.0000627040863,-592.29345703125,7.06598726049842E-6,2.36792169473187E-8,1,2,14.0008964538574,4.98608578147566,32.8399986028671,0.00852171131181834,0.0012492711971589,1,-4.68093862179823E-8,,,,,,,,,,,,,,,,,,,,,4.99994707107544,5.00017833709717,-592.29345703125,-592.29345703125,54.596752068275,5.8404975192101,3.06801247596741,28,1,0,0,1,0.321273803710937,29.3255138397217,1,1,1,5.00017833709717,0,5.0000627040863,,,,,,,,,,,,,,,,,,,,,,,,,,,,,,,,,
,3856107058.3222,4.99994707107544,-1184.95422363281,1.44033857279641E-6,3.94976236514241E-8,1,2,14.0008964538574,4.98627006350259,32.8399986028671,0.00174725214382496,0.000188896097978791,1,-6.41289882621299E-8,,,,,,,,,,,,,,,,,,,,,4.99985313415527,5.00004100799561,-1184.95422363281,-1184.95422363281,54.5592338993519,5.8400915859195,3.06374764442444,28,1,0,0,1,0.321273803710937,28.8367557525635,1,1,1,4.99985313415527,0,4.99994707107544,,,,,,,,,,,,,,,,,,,,,,,,,,,,,,,,,
,3856107082.00519,5.00323867797852,-1777.33325195313,2.06671030282562E-6,1.24212056676479E-8,1,2,14.0008964538574,4.98599700657983,32.8399986028671,0.0024992428790523,0.000320957541743248,1,-5.0568967416523E-8,,,,,,,,,,,,,,,,,,,,,5.00042581558228,5.00605154037476,-1777.33325195313,-1777.33325195313,54.5959704397558,5.84070170419824,3.0589804649353,28,1,0,0,1,0.325775146484375,28.8367557525635,1,1,1,5.00605154037476,0,5.00323867797852,,,,,,,,,,,,,,,,,,,,,,,,,,,,,,,,,
,3856107110.53486,4.99972796440124,-2370.00634765625,5.07714011618487E-6,9.65004350311833E-9,1,2,14.0008964538574,4.98550006511715,32.8399986028671,0.00612467466657842,0.000880820773218912,1,-4.74754198125581E-8,,,,,,,,,,,,,,,,,,,,,4.99914455413818,5.00031137466431,-2370.00634765625,-2370.00634765625,54.5604063421308,5.84071508206298,3.05858063697815,28,1,0,0,1,0.322418212890625,29.3255138397217,1,1,1,4.99914455413818,0,4.99972796440124,,,,,,,,,,,,,,,,,,,,,,,,,,,,,,,,,
,3856107136.03588,4.99841547012329,-2962.60571289063,9.32980718959132E-6,1.04406172027601E-8,1,2,14.0008964538574,4.98559088931495,32.8399986028671,0.0112506436966644,0.00164740985648779,1,-6.33643680844475E-8,,,,,,,,,,,,,,,,,,,,,4.99803304672241,4.99879789352417,-2962.60571289063,-2962.60571289063,54.617074409775,5.83880220027386,3.05312418937683,28,1,0,0,1,0.322723388671875,29.3255138397217,1,1,1,4.99803304672241,0,4.99841547012329,,,,,,,,,,,,,,,,,,,,,,,,,,,,,,,,,
,3856107160.41944,4.99996089935303,-3555.291015625,1.4351736800014E-5,1.12485047793317E-8,1,2,14.0008964538574,4.98569843966046,32.8399986028671,0.0173054431131345,0.00254451205295607,1,-8.89387723574272E-8,,,,,,,,,,,,,,,,,,,,,4.99984645843506,5.000075340271,-3555.291015625,-3555.291015625,54.7874694269673,5.84022298355757,3.05464005470276,28,1,0,0,1,0.319976806640625,28.8367557525635,1,1,1,5.000075340271,0,4.99996089935303,,,,,,,,,,,,,,,,,,,,,,,,,,,,,,,,,
,3856107185.42588,4.99939918518066,-4147.9150390625,1.98094727762506E-5,1.47736164236864E-8,1,2,14.0008964538574,4.9857807843306,32.8399986028671,0.0238817634601104,0.0035462358611585,1,-9.45333464837307E-8,,,,,,,,,,,,,,,,,,,,,4.99936723709106,4.99943113327026,-4147.9150390625,-4147.9150390625,54.5873725260442,5.83961942591027,3.06199431419373,28,1,0,0,1,0.32196044921875,28.8367557525635,1,1,1,4.99943113327026,0,4.99939918518066,,,,,,,,,,,,,,,,,,,,,,,,,,,,,,,,,
,3856107210.18588,4.99982070922852,-4740.220703125,2.55718354257461E-5,1.45447146025207E-8,1,2,14.0008964538574,4.98582687996833,32.8399986028671,0.0308242895006537,0.00460929295348469,1,-9.59378234782049E-8,,,,,,,,,,,,,,,,,,,,,4.99971675872803,4.999924659729,-4740.220703125,-4740.220703125,54.7358819446981,5.84205154907789,3.06423020362854,28,1,0,0,1,0.319671630859375,29.3255138397217,1,1,1,4.99971675872803,0,4.99982070922852,,,,,,,,,,,,,,,,,,,,,,,,,,,,,,,,,
,3856107235.48052,4.99964642524719,-5333.0283203125,3.14726308499084E-5,1.67790903670135E-8,1,2,14.0008964538574,4.98606777656184,32.8399986028671,0.0379326270653617,0.00571924371229687,1,-7.99317850189346E-8,,,,,,,,,,,,,,,,,,,,,4.99947595596313,4.99981689453125,-5333.0283203125,-5333.0283203125,54.5479002858231,5.83917472965584,3.06404423713684,28,1,0,0,1,0.321502685546875,29.3255138397217,1,1,1,4.99981689453125,0,4.99964642524719,,,,,,,,,,,,,,,,,,,,,,,,,,,,,,,,,
,3856107260.67133,4.99969816207886,-5925.60302734375,3.74895416833918E-5,1.73177402975613E-8,1,2,14.0008964538574,4.98623063213046,32.8399986028671,0.0451843544853416,0.00682773629894622,1,-8.29452670341465E-8,,,,,,,,,,,,,,,,,,,,,4.99905872344971,5.00033760070801,-5925.60302734375,-5925.60302734375,54.5424288861885,5.8422309087967,3.06262159347534,28,1,0,0,1,0.3216552734375,29.3255138397217,1,1,1,4.99905872344971,0,4.99969816207886,,,,,,,,,,,,,,,,,,,,,,,,,,,,,,,,,
,3856107285.60735,4.99970841407776,-6518.203125,4.35411841875936E-5,2.10873801927043E-8,1,2,14.0008964538574,4.98635048644975,32.8399986028671,0.0524794497863803,0.00793293572085021,1,-9.40233924254699E-8,,,,,,,,,,,,,,,,,,,,,4.99939918518066,5.00001764297485,-6518.203125,-6518.203125,54.7284564737654,5.83765630063121,3.05174851417542,28,1,0,0,1,0.320205688476562,32.2580642700195,1,1,1,4.99939918518066,0,4.99970841407776,,,,,,,,,,,,,,,,,,,,,,,,,,,,,,,,,
,3856107311.01893,4.99975562095642,-7110.7783203125,4.97401706804329E-5,1.62523694858768E-8,1,2,14.0008964538574,4.98636114918446,32.8399986028671,0.0599482025810765,0.00908167871482141,1,-9.13925703854967E-8,,,,,,,,,,,,,,,,,,,,,4.99961376190186,4.99989748001099,-7110.7783203125,-7110.7783203125,54.7327554306212,5.83632262592908,3.0506865978241,28,1,0,0,1,0.321121215820313,29.3255138397217,1,1,1,4.99989748001099,0,4.99975562095642,,,,,,,,,,,,,,,,,,,,,,,,,,,,,,,,,
,3856107336.13706,5.00000691413879,-7703.43896484375,5.59231839573602E-5,2.01211242133429E-8,1,2,14.0008964538574,4.98644413027579,32.8399986028671,0.0674021367208494,0.0102080352421843,1,-1.05069348383645E-7,,,,,,,,,,,,,,,,,,,,,4.99988842010498,5.00012540817261,-7703.43896484375,-7703.43896484375,54.8480456372077,5.8371373537224,3.05367946624756,28,1,0,0,1,0.320892333984375,28.8367557525635,1,1,1,5.00012540817261,0,5.00000691413879,,,,,,,,,,,,,,,,,,,,,,,,,,,,,,,,,
,3856107368.22036,4.99979400634766,-7999.775390625,5.89530960179124E-5,1.85783126124641E-8,1,2,14.0008964538574,4.98643617967813,32.8399986028671,0.0710407024261974,0.0108465996632206,1,-3.97874036693188E-8,,,,,,,,,,,,,,,,,,,,,4.99979400634766,4.99979400634766,-7999.775390625,-7999.775390625,54.66279967815,5.8374289561584,3.05735421180725,28,1,0,0,1,0.322341918945313,29.3255138397217,1,1,1,4.99979400634766,0,4.99979400634766,,,,,,,,,,,,,,,,,,,,,,,,,,,,,,,,,
,3856107394.37433,4.99992823600769,-8888.6376953125,6.83881192298131E-5,2.43825381038153E-8,1,2,14.0008964538574,4.98648592132962,32.8399986028671,0.0824344991472019,0.0124321679336505,1,-1.71082328596744E-7,,,,,,,,,,,,,,,,,,,,,4.99983263015747,5.00002384185791,-8888.6376953125,-8888.6376953125,54.6717884061212,5.83714746932452,3.05262875556946,28,1,0,0,1,0.322036743164063,29.3255138397217,1,1,1,4.99983263015747,0,4.99992823600769,,,,,,,,,,,,,,,,,,,,,,,,,,,,,,,,,
,3856107424.32,4.99949717521667,-10370.185546875,8.41160309649913E-5,3.07931569048156E-8,1,2,14.0008964538574,4.98657086701218,32.8399986028671,0.101394216211207,0.0152982214800995,1,-2.05003150172134E-7,,,,,,,,,,,,,,,,,,,,,4.99941110610962,4.99958324432373,-10370.185546875,-10370.185546875,54.6893750478039,5.83866756148476,3.05481815338135,28,1,0,0,1,0.32196044921875,29.3255138397217,1,1,1,4.99958324432373,0,4.99949717521667,,,,,,,,,,,,,,,,,,,,,,,,,,,,,,,,,
,3856107453.33006,5.00016212463379,-11851.4638671875,9.99864046979628E-5,3.20351830165432E-8,1,2,14.0008964538574,4.9864038749955,32.8399986028671,0.120503915139178,0.0182811251243638,1,-1.62841603274762E-7,,,,,,,,,,,,,,,,,,,,,5.00012588500977,5.00019836425781,-11851.4638671875,-11851.4638671875,54.7902051267846,5.8383233397055,3.05456686019897,28,1,0,0,1,0.322341918945313,29.8142719268799,1,1,1,5.00019836425781,0,5.00016212463379,,,,,,,,,,,,,,,,,,,,,,,,,,,,,,,,,
,3856107481.66618,5.00023698806763,-13332.9619140625,0.000115776472664538,3.13198517051099E-8,1,2,14.0008964538574,4.98646604530577,32.8399986028671,0.139534489561535,0.021182177009027,1,-1.77198095793456E-7,,,,,,,,,,,,,,,,,,,,,5.00008916854858,5.00038480758667,-13332.9619140625,-13332.9619140625,54.7319738021019,5.83900758416411,3.05669689178467,28,1,0,0,1,0.321807861328125,30.3030319213867,1,1,1,5.00008916854858,0,5.00023698806763,,,,,,,,,,,,,,,,,,,,,,,,,,,,,,,,,
,3856107510.80948,5.00014519691467,-14814.412109375,0.000131747708940477,3.85493496286224E-8,1,2,14.0008964538574,4.98634767750371,32.8399986028671,0.158775157173864,0.0241209217645072,1,-1.87127937093505E-7,,,,,,,,,,,,,,,,,,,,,5.00007963180542,5.00021076202393,-14814.412109375,-14814.412109375,54.6917199333616,5.8385256830164,3.04788613319397,28,1,0,0,1,0.32073974609375,29.3255138397217,1,1,1,5.00021076202393,0,5.00014519691467,,,,,,,,,,,,,,,,,,,,,,,,,,,,,,,,,
,3856107539.01272,4.99994158744812,-16295.8984375,0.000147701282424456,4.33886870357838E-8,1,2,14.0008964538574,4.98634620494803,32.8399986028671,0.177999094286927,0.0270571866437103,1,-1.96982138226113E-7,,,,,,,,,,,,,,,,,,,,,4.99985790252686,5.00002527236938,-16295.8984375,-16295.8984375,54.7589399860154,5.84024512493991,3.0482804775238,28,1,0,0,1,0.321807861328125,29.3255138397217,1,1,1,5.00002527236938,0,4.99994158744812,,,,,,,,,,,,,,,,,,,,,,,,,,,,,,,,,
,3856107570.34737,5.00023126602173,-17777.556640625,0.000163687324349908,3.49050551151855E-8,1,2,14.0008964538574,4.98627907952622,32.8399986028671,0.19725227797055,0.030039455587529,1,-1.73172958142511E-7,,,,,,,,,,,,,,,,,,,,,5.00008344650269,5.00037908554077,-17777.556640625,-17777.556640625,54.9215187180154,5.8404582719724,3.05615282058716,28,1,0,0,1,0.3204345703125,29.3255138397217,1,1,1,5.00038766860962,0,5.00023126602173,,,,,,,,,,,,,,,,,,,,,,,,,,,,,,,,,
,3856107599.8494,4.99988007545471,-19258.833984375,0.000179587043485446,4.29919438979819E-8,1,2,14.0008964538574,4.98633769848009,32.8399986028671,0.216393971009825,0.033100732621314,1,-7.14254490483889E-8,,,,,,,,,,,,,,,,,,,,,4.99972057342529,5.00003957748413,-19258.833984375,-19258.833984375,54.6624088638904,5.8399356756503,3.04781818389893,28,1,0,0,1,0.321273803710937,29.3255138397217,1,1,1,5.00003957748413,0,4.99988007545471,,,,,,,,,,,,,,,,,,,,,,,,,,,,,,,,,
,3856107628.57779,4.99999976158142,-19258.958984375,0.000179345868013787,5.22494227140566E-8,1,2,14.0008964538574,4.98641351421448,32.8399986028671,0.216088753112681,0.0331822640059211,1,3.26453973524306E-8,,,,,,,,,,,,,,,,,,,,,4.99991083145142,5.00008869171143,-19258.958984375,-19258.958984375,54.6655353779673,5.83924486631209,3.04441976547241,28,1,0,0,1,0.321121215820313,28.8367557525635,1,1,1,5.00008869171143,0,4.99999976158142,,,,,,,,,,,,,,,,,,,,,,,,,,,,,,,,,
,3856107657.79718,5.00011801719666,-17777.458984375,0.000163277855810745,4.57272428220406E-8,1,2,14.0008964538574,4.98636662915935,32.8500010073185,0.196723781349399,0.0302252170349413,1,4.31880865909687E-8,,,,,,,,,,,,,,,,,,,,,5.00005149841309,5.00018453598022,-17777.458984375,-17777.458984375,54.54086562915,5.83914712375879,3.046870470047,28,1,0,0,1,0.320205688476562,29.3255138397217,1,1,1,5.00005149841309,0,5.00011801719666,,,,,,,,,,,,,,,,,,,,,,,,,,,,,,,,,
,3856107686.90905,5.000004529953,-16296.021484375,0.000147178548137363,4.20197358850419E-8,1,2,14.0008964538574,4.98646860648739,32.8399986028671,0.177327076282472,0.0272763188746271,1,6.42827362567615E-8,,,,,,,,,,,,,,,,,,,,,4.99997901916504,5.00003004074097,-16296.021484375,-16296.021484375,54.9125299900443,5.83897221779199,3.04601311683655,28,1,0,0,1,0.319137573242188,29.3255138397217,1,1,1,5.00003004074097,0,5.000004529953,,,,,,,,,,,,,,,,,,,,,,,,,,,,,,,,,
,3856107716.16362,5.00014734268188,-14814.5595703125,0.00013109786133775,3.18132265648836E-8,1,2,14.0008964538574,4.98659315501593,32.8399986028671,0.157966905235971,0.0242382174672213,1,8.50404015790314E-9,,,,,,,,,,,,,,,,,,,,,4.99989032745361,5.00040435791016,-14814.5595703125,-14814.5595703125,54.6174652240346,5.83777877649027,3.04603981971741,28,1,0,0,1,0.321197509765625,29.3255138397217,1,1,1,5.00040435791016,0,5.00014734268188,,,,,,,,,,,,,,,,,,,,,,,,,,,,,,,,,
,3856107744.58429,5.00008392333984,-13332.9140625,0.000115087380942422,2.88884664338076E-8,1,2,14.0008964538574,4.98648761272837,32.8399986028671,0.138657457075688,0.0213651206810128,1,8.02121708688759E-8,,,,,,,,,,,,,,,,,,,,,4.99988651275635,5.00028133392334,-13332.9140625,-13332.9140625,54.8460915659097,5.83889962866766,3.04347658157349,28,1,0,0,1,0.320281982421875,28.8367557525635,1,1,1,5.00028133392334,0,5.00008392333984,,,,,,,,,,,,,,,,,,,,,,,,,,,,,,,,,
,3856107775.10488,4.99993109703064,-11851.4267578125,9.91392675174345E-5,2.97851755928339E-8,1,2,14.0008964538574,4.98666756298562,32.8399986028671,0.119444536620805,0.0184356866251703,1,9.42298614257734E-8,,,,,,,,,,,,,,,,,,,,,4.99987316131592,4.99998903274536,-11851.4267578125,-11851.4267578125,54.5412564434096,5.83859938641567,3.0497133731842,28,1,0,0,1,0.320663452148438,29.8142719268799,1,1,1,4.99998903274536,0,4.99993109703064,,,,,,,,,,,,,,,,,,,,,,,,,,,,,,,,,
,3856107806.24634,4.99984955787659,-10370.1982421875,8.32549082055289E-5,2.64594738254582E-8,1,2,14.0008964538574,4.98651755369898,32.8399986028671,0.100296463498549,0.0155211446950603,1,1.12266878432677E-7,,,,,,,,,,,,,,,,,,,,,4.99982404708862,4.99987506866455,-10370.1982421875,-10370.1982421875,54.5760389125154,5.8376858443624,3.04079270362854,28,1,0,0,1,0.321121215820313,29.8142719268799,1,1,1,4.99982404708862,0,4.99984955787659,,,,,,,,,,,,,,,,,,,,,,,,,,,,,,,,,
,3856107836.64704,4.99992609024048,-8888.490234375,6.74076942336158E-5,2.49847821004883E-8,1,2,14.0008964538574,4.98662893409467,32.8399986028671,0.0812032068989141,0.0125984248292227,1,1.1684822378121E-7,,,,,,,,,,,,,,,,,,,,,4.99989032745361,4.99996185302734,-8888.490234375,-8888.490234375,54.6538109501788,5.83684386412418,3.05071377754211,28,1,0,0,1,0.321044921875,28.8367557525635,1,1,1,4.99989032745361,0,4.99992609024048,,,,,,,,,,,,,,,,,,,,,,,,,,,,,,,,,
,3856107864.35026,5.0002019405365,-7999.56689453125,5.79810830211076E-5,2.34485824735018E-8,1,2,14.0008964538574,4.98656948218603,32.8399986028671,0.0698729241476576,0.0106621745701403,1,-4.40998501963888E-8,,,,,,,,,,,,,,,,,,,,,5.00013828277588,5.00026559829712,-7999.56689453125,-7999.56689453125,54.637396751275,5.83727305448573,3.04171252250671,28,1,0,0,1,0.324249267578125,29.3255138397217,1,1,1,5.00026559829712,0,5.0002019405365,,,,,,,,,,,,,,,,,,,,,,,,,,,,,,,,,
,3856107896.06717,4.99986839294434,-7703.365234375,5.47657970854381E-5,2.31028698574467E-8,1,2,14.0008964538574,4.98647763766695,32.8399986028671,0.065978329824096,0.0101890279942096,1,5.65872724509471E-8,,,,,,,,,,,,,,,,,,,,,4.99970960617065,5.00002717971802,-7703.365234375,-7703.365234375,54.6842944624289,5.83675515059131,3.05083274841309,28,1,0,0,1,0.320663452148438,25.904203414917,1,1,1,4.99970960617065,0,4.99986839294434,,,,,,,,,,,,,,,,,,,,,,,,,,,,,,,,,
,3856107921.07511,4.99985098838806,-7110.6796875,4.85320952430413E-5,1.71516422429901E-8,1,2,14.0008964538574,4.98650871202079,32.8399986028671,0.0584655328879238,0.00905113293468936,1,6.82297175749736E-8,,,,,,,,,,,,,,,,,,,,,4.99981164932251,4.99989032745361,-7110.6796875,-7110.6796875,54.4587946346308,5.8376618093929,3.04871511459351,28,1,0,0,1,0.321578979492188,29.3255138397217,1,1,1,4.99989032745361,0,4.99985098838806,,,,,,,,,,,,,,,,,,,,,,,,,,,,,,,,,
,3856107944.56997,4.99889850616455,-6518.3251953125,4.23359464531061E-5,1.85329353556865E-8,1,2,14.0008964538574,4.98647718878442,32.8399986028671,0.0509996917085505,0.00790219300658293,1,6.50780876134675E-8,,,,,,,,,,,,,,,,,,,,,4.99871683120728,4.99908018112183,-6518.3251953125,-6518.3251953125,54.6956280759577,5.83713569701069,3.03884720802307,28,1,0,0,1,0.321426391601562,29.3255138397217,1,1,1,4.99918222427368,0,4.99889850616455,,,,,,,,,,,,,,,,,,,,,,,,,,,,,,,,,
,3856107973.12695,5.00008153915405,-5926.2763671875,3.61323623316742E-5,1.79049177909214E-8,1,2,14.0008964538574,4.98637559823517,32.8399986028671,0.0435314814854506,0.00670407699922814,1,2.23465782500197E-8,,,,,,,,,,,,,,,,,,,,,5.00005865097046,5.00010442733765,-5926.2763671875,-5926.2763671875,54.718686117275,5.83918546474183,3.0406014919281,28,1,0,0,1,0.322113037109375,28.8367557525635,1,1,1,5.00005865097046,0,5.00008153915405,,,,,,,,,,,,,,,,,,,,,,,,,,,,,,,,,
,3856107997.1184,4.99984765052795,-5333.0771484375,3.00230858605219E-5,1.49428470353812E-8,1,2,14.0008964538574,4.98636141844156,32.8399986028671,0.0361638197289092,0.00561743681945156,1,5.75016581724272E-8,,,,,,,,,,,,,,,,,,,,,4.9998049736023,4.99989032745361,-5333.0771484375,-5333.0771484375,54.6964097044769,5.83818458555924,3.04036498069763,28,1,0,0,1,0.321502685546875,29.3255138397217,1,1,1,4.9998049736023,0,4.99984765052795,,,,,,,,,,,,,,,,,,,,,,,,,,,,,,,,,
,3856108022.61805,4.99994421005249,-4740.5390625,2.4000622320897E-5,1.1851337643218E-8,1,2,14.0008964538574,4.9865857322821,32.8399986028671,0.0289106201778184,0.00449585100415074,1,5.00815952991325E-8,,,,,,,,,,,,,,,,,,,,,4.99982976913452,5.00005865097046,-4740.5390625,-4740.5390625,54.5502451713808,5.8358130925197,3.03852844238281,28,1,0,0,1,0.320663452148438,29.3255138397217,1,1,1,5.00005865097046,0,4.99994421005249,,,,,,,,,,,,,,,,,,,,,,,,,,,,,,,,,
,3856108045.72682,5.0001814365387,-4147.6943359375,1.8146573089872E-5,9.96949806399031E-9,1,2,14.0008964538574,4.98662959919905,32.8399986028671,0.021855277799775,0.00342507373491286,1,5.92561925017754E-8,,,,,,,,,,,,,,,,,,,,,5.00016117095947,5.00020170211792,-4147.6943359375,-4147.6943359375,54.6499028075827,5.83718798112022,3.03334355354309,28,1,0,0,1,0.321121215820313,28.8367557525635,1,1,1,5.00020170211792,0,5.0001814365387,,,,,,,,,,,,,,,,,,,,,,,,,,,,,,,,,
,3856108068.26237,4.99993824958801,-3555.14404296875,1.24516292439073E-5,1.16619834763065E-8,1,2,14.0008964538574,4.98667212539591,32.8399986028671,0.0149898546486434,0.00239425073060446,1,7.72083447440831E-8,,,,,,,,,,,,,,,,,,,,,4.99972915649414,5.00014734268188,-3555.14404296875,-3555.14404296875,54.5826827549289,5.83787325528302,3.02386045455933,28,1,0,0,1,0.321578979492188,29.3255138397217,1,1,1,5.00014734268188,0,4.99993824958801,,,,,,,,,,,,,,,,,,,,,,,,,,,,,,,,,
,3856108091.56273,4.9999361038208,-2962.642578125,6.98743241007846E-6,1.11261715399476E-8,1,2,14.0008964538574,4.98662457516897,32.8399986028671,0.00840592486620296,0.00138111865461396,1,7.45009315705207E-8,,,,,,,,,,,,,,,,,,,,,4.99981546401978,5.00005674362183,-2962.642578125,-2962.642578125,54.6393508225731,5.83721591198116,3.03208327293396,28,1,0,0,1,0.321502685546875,29.3255138397217,1,1,1,5.00005674362183,0,4.9999361038208,,,,,,,,,,,,,,,,,,,,,,,,,,,,,,,,,
,3856108114.91235,4.99992966651916,-2370.361328125,1.79570441030055E-6,9.77857806230313E-9,1,2,14.0008964538574,4.98655249037363,32.8399986028671,0.00214949340245061,0.000424734602396063,1,7.70796862977704E-8,,,,,,,,,,,,,,,,,,,,,4.99989366531372,4.99996566772461,-2370.361328125,-2370.361328125,54.7612848715731,5.83665621635487,3.0341854095459,28,1,0,0,1,0.319747924804687,29.3255138397217,1,1,1,4.99996566772461,0,4.99992966651916,,,,,,,,,,,,,,,,,,,,,,,,,,,,,,,,,
,3856108138.10688,5.00016641616821,-1777.45581054687,-2.91196741931586E-6,9.8753695904255E-9,1,2,14.0008964538574,4.98668349243095,32.8399986028671,-0.00352370829880416,-0.000441689689991011,1,8.00663267532854E-8,,,,,,,,,,,,,,,,,,,,,5.00014877319336,5.00018405914307,-1777.45581054687,-1777.45581054687,54.7022719183712,5.83575680345991,3.03262066841126,28,1,0,0,1,0.32135009765625,27.8592376708984,1,1,1,5.00018405914307,0,5.00016641616821,,,,,,,,,,,,,,,,,,,,,,,,,,,,,,,,,
,3856108161.40575,5.00016188621521,-1185.11328125,-6.92146463441638E-6,1.3360736292959E-8,1,2,14.0008964538574,4.98655970556261,32.8399986028671,-0.0083577746442413,-0.00116357749567207,1,9.58994245500165E-8,,,,,,,,,,,,,,,,,,,,,4.9999885559082,5.00033521652222,-1185.11328125,-1185.11328125,54.4228397227461,5.83698231828412,3.03692865371704,28,1,0,0,1,0.322418212890625,30.3030319213867,1,1,1,5.00033521652222,0,5.00016188621521,,,,,,,,,,,,,,,,,,,,,,,,,,,,,,,,,
,3856108185.14449,4.9997923374176,-592.954528808594,-9.79214964302104E-6,1.00459307795921E-8,1,2,14.0008964538574,4.98651953609276,32.8399986028671,-0.0118079822913268,-0.0017508346940445,1,4.87975962370309E-8,,,,,,,,,,,,,,,,,,,,,4.99967813491821,4.99990653991699,-592.954528808594,-592.954528808594,54.5096004883808,5.83704671296879,3.0362753868103,28,1,0,0,1,0.32379150390625,29.3255138397217,1,1,1,4.99967813491821,0,4.9997923374176,,,,,,,,,,,,,,,,,,,,,,,,,,,,,,,,,
,3856108208.38047,5.00007438659668,-0.0856923758983612,-1.0720128635381E-5,1.57369960668126E-8,1,2,14.0008964538574,4.98645267628521,32.8399986028671,-0.0129318904325583,-0.00188323294237334,1,8.12149840412347E-8,,,,,,,,,,,,,,,,,,,,,5.00004863739014,5.00010013580322,-0.0856923758983612,-0.0856923758983612,54.7859061699289,5.83605058942785,3.03166365623474,28,1,0,0,1,0.319976806640625,29.3255138397217,1,1,1,5.00010013580322,0,5.00007438659668,,,,,,,,,,,,,,,,,,,,,,,,,,,,,,,,,
,3856108229.90549,5.00023460388184,592.158813476563,-6.54192796587194E-6,3.23208370749353E-8,1,2,14.0008964538574,4.98629742759064,32.8399986028671,-0.00788556016891024,-0.0011866455792053,1,1.84721543024422E-8,,,,,,,,,,,,,,,,,,,,,5.00014543533325,5.00032377243042,592.158813476563,592.158813476563,54.6010510251308,5.83804978697386,3.03672313690186,28,1,0,0,1,0.3216552734375,29.3255138397217,1,1,1,5.00014543533325,0,5.00023460388184,,,,,,,,,,,,,,,,,,,,,,,,,,,,,,,,,
,3856108252.26836,4.99997019767761,1184.67260742188,-1.23496839197209E-6,4.10066559718094E-8,1,2,14.0008964538574,4.98637104170219,32.8399986028671,-0.00149682090261413,-0.000170719465703964,1,4.77210691251404E-8,,,,,,,,,,,,,,,,,,,,,4.99992704391479,5.00001335144043,1184.67260742188,1184.67260742188,54.6905474905827,5.83743456567633,3.03613328933716,28,1,0,0,1,0.3204345703125,29.3255138397217,1,1,1,4.99992704391479,0,4.99997019767761,,,,,,,,,,,,,,,,,,,,,,,,,,,,,,,,,
,3856108275.19202,4.99980187416077,1777.38232421875,-2.06712720033365E-6,1.56015264068783E-8,1,2,14.0008964538574,4.98633858287148,32.8399986028671,-0.00250008797690826,-0.000320393876018294,1,5.11262855904177E-8,,,,,,,,,,,,,,,,,,,,,4.99976539611816,4.99983835220337,1777.38232421875,1777.38232421875,54.5654869275058,5.83626445024764,3.03815627098084,28,1,0,0,1,0.320663452148438,28.8367557525635,1,1,1,4.99976539611816,0,4.99980187416077,,,,,,,,,,,,,,,,,,,,,,,,,,,,,,,,,
,3856108298.97851,5.00002074241638,2370.60620117187,-5.15545184980179E-6,1.26196105702419E-8,1,2,14.0008964538574,4.98641921091295,32.8399986028671,-0.00622406096280332,-0.000873049530305367,1,6.61246928061854E-8,,,,,,,,,,,,,,,,,,,,,4.99998092651367,5.00006055831909,2370.60620117187,2370.60620117187,54.4408171786884,5.83643755904012,3.0299756526947,28,1,0,0,1,0.322189331054687,29.8142719268799,1,1,1,4.99998092651367,0,5.00002074241638,,,,,,,,,,,,,,,,,,,,,,,,,,,,,,,,,
,3856108323.21616,4.99984502792358,2963.38940429687,-9.44084121293213E-6,1.40178302539519E-8,1,2,14.0008964538574,4.98654879368156,32.8500010073185,-0.0113868633310368,-0.0016722754785761,1,6.01256111327444E-8,,,,,,,,,,,,,,,,,,,,,4.9997706413269,4.99991941452026,2963.38940429687,2963.38940429687,54.5658777417654,5.83791074908803,3.03878211975098,28,1,0,0,1,0.32012939453125,28.8367557525635,1,1,1,4.99991941452026,0,4.99984502792358,,,,,,,,,,,,,,,,,,,,,,,,,,,,,,,,,
,3856108347.10256,4.9998209476471,3555.93969726562,-1.44622681976814E-5,1.90481203317274E-8,1,2,14.0008964538574,4.98656109555972,32.8399986028671,-0.0174434835726259,-0.00256124391315526,1,9.25170853667938E-8,,,,,,,,,,,,,,,,,,,,,4.99969530105591,4.99994659423828,3555.93969726562,3555.93969726562,54.5721307699192,5.83584546733645,3.03544688224793,28,1,0,0,1,0.322113037109375,29.3255138397217,1,1,1,4.99969530105591,0,4.9998209476471,,,,,,,,,,,,,,,,,,,,,,,,,,,,,,,,,
,3856108371.21613,4.99993205070496,4148.61279296875,-1.98771999107245E-5,1.12916154880708E-8,1,2,14.0008964538574,4.98652367963034,32.8399986028671,-0.0239727422629033,-0.00353088462485433,1,1.18275217732754E-7,,,,,,,,,,,,,,,,,,,,,4.99977874755859,5.00008535385132,4148.61279296875,4148.61279296875,54.4732547622365,5.83697369085773,3.03623676300049,28,1,0,0,1,0.322265625,29.3255138397217,1,1,1,5.00008535385132,0,4.99993205070496,,,,,,,,,,,,,,,,,,,,,,,,,,,,,,,,,
,3856108395.01913,4.99999451637268,4741.16357421875,-2.56223219634426E-5,1.43071129859524E-8,1,2,14.0008964538574,4.98650763203858,32.8399986028671,-0.0309006610878361,-0.0045566251538431,1,1.48122572603529E-7,,,,,,,,,,,,,,,,,,,,,4.99984979629517,5.0001392364502,4741.16357421875,4741.16357421875,54.5944071827173,5.83651683134105,3.03935742378235,28,1,0,0,1,0.32135009765625,30.7917900085449,1,1,1,5.0001392364502,0,4.99999451637268,,,,,,,,,,,,,,,,,,,,,,,,,,,,,,,,,
,3856108418.03453,5.00023293495178,5333.61572265625,-3.15008372869148E-5,1.60993387965267E-8,1,2,14.0008964538574,4.9865009040542,32.8399986028671,-0.0379868822655488,-0.00562309078733586,1,1.64634603452956E-7,,,,,,,,,,,,,,,,,,,,,5.00004243850708,5.00042343139648,5333.61572265625,5333.61572265625,54.7100882035635,5.83699975510022,3.0346565246582,28,1,0,0,1,0.321502685546875,30.7917900085449,1,1,1,5.00042343139648,0,5.00023293495178,,,,,,,,,,,,,,,,,,,,,,,,,,,,,,,,,
,3856108442.61498,5.00001549720764,5926.25244140625,-3.75238079782778E-5,1.72922005666432E-8,1,2,14.0008964538574,4.98654743870264,32.8399986028671,-0.0452435602849077,-0.00674407337900575,1,1.58137628542134E-7,,,,,,,,,,,,,,,,,,,,,4.99993944168091,5.00009155273438,5926.25244140625,5926.25244140625,54.6870301622462,5.8359806040166,3.03714394569397,28,1,0,0,1,0.321578979492188,29.3255138397217,1,1,1,5.00009155273438,0,5.00001549720764,,,,,,,,,,,,,,,,,,,,,,,,,,,,,,,,,
,3856108466.63328,5.00048565864563,6518.986328125,-4.36220575208509E-5,1.86325394172231E-8,1,2,14.0008964538574,4.98632974218503,32.8399986028671,-0.0525893069213785,-0.00786489579949792,1,1.6285918328732E-7,,,,,,,,,,,,,,,,,,,,,5.00038528442383,5.00058603286743,6518.986328125,6518.986328125,54.5287503871019,5.83661768700691,3.04159069061279,28,1,0,0,1,0.322189331054687,29.8142719268799,1,1,1,5.00038528442383,0,5.00048565864563,,,,,,,,,,,,,,,,,,,,,,,,,,,,,,,,,
,3856108491.62866,4.99974298477173,7111.6103515625,-4.9761647169759E-5,2.06282957685123E-8,1,2,14.0008964538574,4.98644621465383,32.8399986028671,-0.0599929700587048,-0.00897203792191302,1,1.85861068427258E-7,,,,,,,,,,,,,,,,,,,,,4.9997410774231,4.99974489212036,7111.6103515625,7111.6103515625,54.6276263947846,5.83656349618472,3.03834295272827,28,1,0,0,1,0.32440185546875,29.3255138397217,1,1,1,4.9997410774231,0,4.99974298477173,,,,,,,,,,,,,,,,,,,,,,,,,,,,,,,,,
,3856108516.10823,4.99991726875305,7703.8671875,-5.59478463911928E-5,2.00057599839035E-8,1,2,14.0008964538574,4.98648116052829,32.8399986028671,-0.0674498409600102,-0.0100999877227655,1,1.98611323741911E-7,,,,,,,,,,,,,,,,,,,,,4.99984931945801,4.9999852180481,7703.8671875,7703.8671875,54.7792623275154,5.83510357883191,3.04068875312805,28,1,0,0,1,0.320816040039063,30.7917900085449,1,1,1,4.9999852180481,0,4.99991726875305,,,,,,,,,,,,,,,,,,,,,,,,,,,,,,,,,
,3856108547.78103,5.00007057189941,8000.19140625,-5.90549505514585E-5,2.103871841077E-8,1,2,14.0008964538574,4.98641869655237,32.8399986028671,-0.0711884908440623,-0.0106996805943263,1,1.7729879818078E-7,,,,,,,,,,,,,,,,,,,,,5.00007057189941,5.00007057189941,8000.19140625,8000.19140625,54.7214218170923,5.83697239905798,3.03654670715332,28,1,0,0,1,0.320587158203125,28.8367557525635,1,1,1,5.00007057189941,0,5.00007057189941,,,,,,,,,,,,,,,,,,,,,,,,,,,,,,,,,
,3856108573.92029,4.99996733665466,9125.2216796875,-7.09171981828717E-5,2.33745553974833E-8,1,2,14.0008964538574,4.98643153922292,32.8399986028671,-0.0854978939847346,-0.0127863073814694,1,2.64901834391496E-7,,,,,,,,,,,,,,,,,,,,,4.99996471405029,4.99996995925903,9125.2216796875,9125.2216796875,54.7589399860154,5.8370151431137,3.03919243812561,28,1,0,0,1,0.319671630859375,29.3255138397217,1,1,1,4.99996995925903,0,4.99996733665466,,,,,,,,,,,,,,,,,,,,,,,,,,,,,,,,,
,3856108602.26753,4.99982452392578,10575.1611328125,-8.63443242905753E-5,2.63061291292695E-8,1,2,14.0008964538574,4.98681143662005,32.8399986028671,-0.104099518792544,-0.0156245672372341,1,2.7680169343585E-7,,,,,,,,,,,,,,,,,,,,,4.99969530105591,4.99995374679565,10575.1611328125,10575.1611328125,54.8054468829097,5.83505240252401,3.03083467483521,28,1,0,0,1,0.321884155273438,28.3479976654053,1,1,1,4.99995374679565,0,4.99982452392578,,,,,,,,,,,,,,,,,,,,,,,,,,,,,,,,,
,3856108629.96981,5.00050354003906,12024.7822265625,-0.000101806581389492,2.74250277932492E-8,1,2,14.0008964538574,4.98642794121059,32.8399986028671,-0.122711990047177,-0.0185256120035663,1,2.39199829790772E-7,,,,,,,,,,,,,,,,,,,,,5.00029277801514,5.00071430206299,12024.7822265625,12024.7822265625,54.6022234679096,5.83758045443185,3.03208327293396,28,1,0,0,1,0.321044921875,29.3255138397217,1,1,1,5.00029277801514,0,5.00050354003906,,,,,,,,,,,,,,,,,,,,,,,,,,,,,,,,,
,3856108657.7086,4.99988269805908,13474.4892578125,-0.000117411718286339,3.57032153025696E-8,1,2,14.0008964538574,4.98682917372564,32.8399986028671,-0.14156409707577,-0.0211942613975341,1,4.19763796205533E-7,,,,,,,,,,,,,,,,,,,,,4.99955701828003,5.00020837783814,13474.4892578125,13474.4892578125,54.698363775775,5.83823122032662,3.03387904167175,28,1,0,0,1,0.321426391601562,29.3255138397217,1,1,1,5.00020837783814,0,4.99988269805908,,,,,,,,,,,,,,,,,,,,,,,,,,,,,,,,,
,3856108686.38559,5.00021958351135,14924.7587890625,-0.000132964388266628,4.10460064689255E-8,1,2,14.0008964538574,4.98706323109425,32.8399986028671,-0.160311169855079,-0.0241038453810202,1,3.91924924964789E-7,,,,,,,,,,,,,,,,,,,,,5.00009202957153,5.00034713745117,14924.7587890625,14924.7587890625,54.4564497490731,5.83835551240794,3.0371425151825,28,1,0,0,1,0.320587158203125,29.8142719268799,1,1,1,5.00009202957153,0,5.00021958351135,,,,,,,,,,,,,,,,,,,,,,,,,,,,,,,,,
,3856108714.83215,5.00008010864258,16374.8212890625,-0.000148531797482814,4.13862467030537E-8,1,2,14.0008964538574,4.98695235210019,32.8399986028671,-0.179087164064823,-0.0268441474991016,1,5.04965489224658E-7,,,,,,,,,,,,,,,,,,,,,4.99994516372681,5.00021505355835,16374.8212890625,16374.8212890625,54.894552534102,5.8369376151844,3.03876447677612,28,1,0,0,1,0.321121215820313,29.8142719268799,1,1,1,4.99994516372681,0,5.00008010864258,,,,,,,,,,,,,,,,,,,,,,,,,,,,,,,,,
,3856108743.45114,5.0000147819519,17824.736328125,-0.000164142304488953,3.89153271184881E-8,1,2,14.0008964538574,4.98675553775984,32.8399986028671,-0.197887825868071,-0.0297305502767454,1,5.02638700906804E-7,,,,,,,,,,,,,,,,,,,,,4.99997091293335,5.00005865097046,17824.736328125,17824.736328125,54.7519053293423,5.83701251700837,3.03666424751282,28,1,0,0,1,0.322189331054687,28.8367557525635,1,1,1,4.99997091293335,0,5.0000147819519,,,,,,,,,,,,,,,,,,,,,,,,,,,,,,,,,
,3856108771.95244,4.99998664855957,19274.75,-0.000179782217117327,3.7335437628053E-8,1,2,14.0008964538574,4.98693441265256,32.8399986028671,-0.216742846591197,-0.0326376365905531,1,4.90249062475604E-7,,,,,,,,,,,,,,,,,,,,,4.99975299835205,5.00022029876709,19274.75,19274.75,54.9273809319096,5.83691462912776,3.03816866874695,28,1,0,0,1,0.320205688476562,29.3255138397217,1,1,1,4.99975299835205,0,4.99998664855957,,,,,,,,,,,,,,,,,,,,,,,,,,,,,,,,,
,3856108786.05154,4.99986720085144,19999.6953125,-0.000187664817334136,5.34932894385811E-8,1,2,14.0008964538574,4.98694375432931,32.8399986028671,-0.226226236475714,-0.0342014331933934,1,4.01626448337792E-7,,,,,,,,,,,,,,,,,,,,,4.99980592727661,4.99992847442627,19999.6953125,19999.6953125,54.8347579523808,5.8371025979986,3.03349375724793,28,1,0,0,1,0.3216552734375,29.8142719268799,1,1,1,4.99980592727661,0,4.99986720085144,,,,,,,,,,,,,,,,,,,,,,,,,,,,,,,,,