File: example_data/S2_Cu-OOP-MH@5K_3kOe_course_1500Oe_fine-separate_run.dat
[Header]
; MPMS3 Data File (default extension .dat)
; Copyright (c) 2007, Quantum Design, Inc. All rights reserved.
TITLE,
FILEOPENTIME,3856361845.89141,03/13/2022,7:36 pm
BYAPP,MPMS3 w/ AC,1.0,1.1
INFO,MPMS3 Measurement Release 1.1.16 Build 424, MultiVu Release 2.3.4.19,APPNAME
INFO,Linear Motor Servo Controller,MOTOR_MODULE_NAME
INFO,3101-100 M0,MOTOR_HW_VERSION
INFO,MMC901,MOTOR_SERIAL_NUMBER
INFO,01.04.28,MOTOR_SOFTWARE_VERSION
INFO,Quantum Design Squid Module,SQUID_MODULE_NAME
INFO,3101-501 B0,SQUID_HW_VERSION
INFO,SQM233,SQUID_SERIAL_NUMBER
INFO,01.03.04,SQUID_SOFTWARE_VERSION
INFO,Quantum Design VSM Oven,OVEN_MODULE_NAME
INFO,3101-201 A3,OVEN_HW_VERSION
INFO,OVB284,OVEN_SERIAL_NUMBER
INFO,01.07.07,OVEN_SOFTWARE_VERSION
INFO,SQUID AC,AC_MODULE_NAME
INFO,3101-401 F2,AC_HW_VERSION
INFO,SAC147,AC_SERIAL_NUMBER
INFO,SQUID AC 00.95.07,AC_SOFTWARE_VERSION
INFO,TCI231-2,COIL_SERIAL_NUMBER
INFO,0,MOMENT_UNITS
INFO,S2,SAMPLE_MATERIAL
INFO,OOP,SAMPLE_COMMENT
INFO,,SAMPLE_MASS
INFO,,SAMPLE_VOLUME
INFO,,SAMPLE_MOLECULAR_WEIGHT
INFO,,SAMPLE_SIZE
INFO,,SAMPLE_SHAPE
INFO,Standard,SAMPLE_HOLDER
INFO,Standard,SAMPLE_HOLDER_DETAIL
INFO,52.18,SAMPLE_OFFSET
DATATYPE,COMMENT,1
DATATYPE,TIME,2
STARTUPAXIS,X,2
STARTUPAXIS,Y1,5
FIELDGROUP, VSM,2,3,4,5,6,8,9,10,11,14,15
FIELDGROUP, DC, 2,3,4,14,56,57,58,59,60,61,62,63,64,65,66,67,68,69
FIELDGROUP, AC, 2,3,4,11,16,17,18,19,20,21,22,23,24,25,26,27,28,29,30
STARTUPGROUP, All
[Data]
Comment,Time Stamp (sec),Temperature (K),Magnetic Field (Oe),Moment (emu),M. Std. Err. (emu),Transport Action,Averaging Time (sec),Frequency (Hz),Peak Amplitude (mm),Center Position (mm),Lockin Signal' (V),Lockin Signal (V),Range,M. Quad. Signal (emu),AC Moment (emu),AC M. Std Err. (emu),AC Phase (deg),AC Phase Std. Err. (deg),AC Susceptibility (emu/Oe),AC Suscept. Std Err. (emu/Oe),AC X' (emu/Oe),AC X' Std Err. (emu/Oe),AC X'' (emu/Oe),AC X'' Std Err. (emu/Oe),AC Drive (Oe),AC Frequency (Hz),AC Averaging Time (sec),AC Cycles,AC Range,AC Measure Type,AC Signal' (V),AC Signal'' (V),AC Trim Coil Ratio,AC Trim Coil Phase,Min. Temperature (K),Max. Temperature (K),Min. Field (Oe),Max. Field (Oe),Mass (grams),Motor Lag (deg),Pressure (Torr),Measure Count,Measurement Number,SQUID Status (code),Motor Status (code),Measure Status (code),Motor Current (amps),Motor Temp. (C),Temp. Status (code),Field Status (code),Chamber Status (code),Chamber Temp (K),Redirection State,Average Temp (K),Rotation Angle (deg),Rotator state,DC Moment Fixed Ctr (emu),DC Moment Err Fixed Ctr (emu),DC Moment Free Ctr (emu),DC Moment Err Free Ctr (emu),DC Fixed Fit,DC Free Fit,DC Calculated Center (mm),DC Calculated Center Err (mm),DC Scan Length (mm),DC Scan Time (s),DC Number of Points,DC Squid Drift,DC Min V (V),DC Max V (V),DC Scans per Measure,Map 01,Map 02,Map 03,Map 04,Map 05,Map 06,Map 07,Map 08,Map 09,Map 10,Map 11,Map 12,Map 13,Map 14,Map 15,Map 16
,3856361870.92685,5.00004291534424,-0.293802440166473,1.40721928150184E-5,6.72406723600286E-9,1,2,14.0008964538574,4.99353841532356,34.850001335144,0.0169936537976977,0.00257915782815747,1,-2.20082871140115E-8,,,,,,,,,,,,,,,,,,,,,5.00004291534424,5.00004291534424,-0.293802440166473,-0.293802440166473,54.5283595728423,5.79164487590844,2.78276181221008,28,1,0,0,1,0.325393676757812,27.3704795837402,1,1,1,5.00004291534424,0,5.00004291534424,,,,,,,,,,,,,,,,,,,,,,,,,,,,,,,,,
,3856361903.85321,4.99991583824158,899.610778808594,2.3692110572939E-5,9.70967715211585E-8,1,2,14.0008964538574,4.99321229464547,34.850001335144,0.0286032991459446,0.00437322688693959,1,-1.11067993758116E-8,,,,,,,,,,,,,,,,,,,,,4.99988126754761,4.99995040893555,899.610778808594,899.610778808594,54.6287988375635,5.79270570856056,2.78602075576782,28,1,0,0,1,0.323028564453125,27.3704795837402,1,1,1,4.99995040893555,0,4.99991583824158,,,,,,,,,,,,,,,,,,,,,,,,,,,,,,,,,
,3856361940.12611,5.00005102157593,1799.60119628906,4.4120481047257E-5,1.44862475339805E-8,1,2,14.0008964538574,4.99298561023454,34.850001335144,0.0532537092810187,0.0082036015289296,1,2.91081355947533E-8,,,,,,,,,,,,,,,,,,,,,4.99997186660767,5.00013017654419,1799.60119628906,1799.60119628906,54.7179044887558,5.79379183844143,2.78475975990295,28,1,0,0,1,0.324325561523438,27.8592376708984,1,1,1,5.00013017654419,0,5.00005102157593,,,,,,,,,,,,,,,,,,,,,,,,,,,,,,,,,
,3856361976.37257,4.9999692440033,2699.81176757813,5.08466411624394E-5,1.05879527210492E-8,1,2,14.0008964538574,4.99282515335564,34.8600000143051,0.0613725432397556,0.00943377295615127,1,1.69425022420342E-8,,,,,,,,,,,,,,,,,,,,,4.99996185302734,4.99997663497925,2699.81176757813,2699.81176757813,54.6135570814385,5.79391198493854,2.78007793426514,28,1,0,0,1,0.322799682617188,28.3479976654053,1,1,1,4.99996185302734,0,4.9999692440033,,,,,,,,,,,,,,,,,,,,,,,,,,,,,,,,,
,3856362019.02662,4.99996876716614,2699.82397460938,5.07818873663647E-5,7.40039072328534E-9,1,2,14.0008964538574,4.99257242314747,34.8600000143051,0.0613106652785102,0.0092866398029606,1,-9.44735836818566E-8,,,,,,,,,,,,,,,,,,,,,4.99988746643066,5.00005006790161,2699.82397460938,2699.82397460938,54.6979729615154,5.79514203718691,2.78506636619568,28,1,0,0,1,0.323944091796875,28.3479976654053,1,1,1,4.99988746643066,0,4.99996876716614,,,,,,,,,,,,,,,,,,,,,,,,,,,,,,,,,
,3856362053.48937,4.99953627586365,1799.73583984375,4.39479976018948E-5,1.11359556451571E-8,1,2,14.0008964538574,4.99239605918331,34.850001335144,0.053057546593131,0.00803464032205932,1,-8.33075746527889E-8,,,,,,,,,,,,,,,,,,,,,4.99953413009644,4.99953842163086,1799.73583984375,1799.73583984375,54.5955796254962,5.79617323673831,2.77874565124512,28,1,0,0,1,0.326309204101562,27.8592376708984,1,1,1,4.99953413009644,0,4.99953627586365,,,,,,,,,,,,,,,,,,,,,,,,,,,,,,,,,
,3856362094.81644,4.99998354911804,1469.79565429687,4.1399608891525E-5,1.14252276868592E-8,1,2,14.0008964538574,4.99216746482929,34.850001335144,0.0499659184253829,0.00764523870288954,1,-1.46881158650689E-8,,,,,,,,,,,,,,,,,,,,,4.9999532699585,5.00001382827759,1469.79565429687,1469.79565429687,54.6131662671789,5.79671803678753,2.7802255153656,28,1,0,0,1,0.326385498046875,28.3479976654053,1,1,1,4.9999532699585,0,4.99998354911804,,,,,,,,,,,,,,,,,,,,,,,,,,,,,,,,,
,3856362129.33111,4.99631547927856,1379.58605957031,4.0662672069824E-5,1.01642640923838E-8,1,2,14.0008964538574,4.99215896659215,34.8600000143051,0.0490698687827547,0.00755158153063712,1,2.07478740136002E-8,,,,,,,,,,,,,,,,,,,,,4.99575042724609,4.99688053131103,1379.58605957031,1379.58605957031,54.6166835955154,5.79722026585388,2.76603150367737,28,1,0,0,1,0.326995849609375,28.3479976654053,1,1,1,4.99688053131103,0,4.99631547927856,,,,,,,,,,,,,,,,,,,,,,,,,,,,,,,,,
,3856362164.11511,5.00025200843811,1289.68249511719,3.99429928761608E-5,1.18428043941751E-8,1,2,14.0008964538574,4.99201068327251,34.8600000143051,0.0481991967373394,0.00741887570476338,1,2.14215478647399E-8,,,,,,,,,,,,,,,,,,,,,4.99990892410278,5.00059509277344,1289.68249511719,1289.68249511719,54.72376670265,5.79682026259654,2.75703620910645,28,1,0,0,1,0.319061279296875,29.8142719268799,1,1,1,4.99990892410278,0,5.00025200843811,,,,,,,,,,,,,,,,,,,,,,,,,,,,,,,,,
,3856362196.27201,4.99986600875854,1199.9013671875,3.92325957595227E-5,9.97094666698331E-9,1,2,14.0008964538574,4.99186417070207,34.850001335144,0.0473376902199159,0.00730179855668084,1,3.36105518784152E-8,,,,,,,,,,,,,,,,,,,,,4.99981021881103,4.99992179870605,1199.9013671875,1199.9013671875,54.7945040836404,5.79797500998036,2.74665451049805,28,1,0,0,1,0.32257080078125,28.3479976654053,1,1,1,4.99992179870605,0,4.99986600875854,,,,,,,,,,,,,,,,,,,,,,,,,,,,,,,,,
,3856362228.49306,4.99989986419678,1109.93664550781,3.85079496455382E-5,1.27946297415761E-8,1,2,14.0008964538574,4.99173341608544,34.850001335144,0.046460218903517,0.00717590751196064,1,4.06466106087334E-8,,,,,,,,,,,,,,,,,,,,,4.9997673034668,5.00003242492676,1109.93664550781,1109.93664550781,54.6198101095923,5.79858126518437,2.74482560157776,28,1,0,0,1,0.324478149414063,28.3479976654053,1,1,1,4.9997673034668,0,4.99989986419678,,,,,,,,,,,,,,,,,,,,,,,,,,,,,,,,,
,3856362260.27308,4.9999086856842,1019.91064453125,3.77860857185931E-5,1.26443967988332E-8,1,2,14.0008964538574,4.99166958208988,34.850001335144,0.0455854484840231,0.00706094579822686,1,5.61960607172515E-8,,,,,,,,,,,,,,,,,,,,,4.99983978271484,4.99997758865356,1019.91064453125,1019.91064453125,54.4658292913038,5.79911297803566,2.73941946029663,28,1,0,0,1,0.319900512695313,28.8367557525635,1,1,1,4.99997758865356,0,4.9999086856842,,,,,,,,,,,,,,,,,,,,,,,,,,,,,,,,,
,3856362291.47911,4.99994039535522,929.872436523437,3.70220641241171E-5,1.11305692562401E-8,1,2,14.0008964538574,4.99158694487078,34.850001335144,0.0446607562238802,0.00693063621006123,1,6.55189112612762E-8,,,,,,,,,,,,,,,,,,,,,4.99984741210937,5.00003337860107,929.872436523437,929.872436523437,54.8027111830923,5.7993612927121,2.7428674697876,28,1,0,0,1,0.325469970703125,27.8592376708984,1,1,1,5.00003337860107,0,4.99994039535522,,,,,,,,,,,,,,,,,,,,,,,,,,,,,,,,,
,3856362324.65705,5.00004434585571,839.895446777344,3.62608293435428E-5,1.3136604190756E-8,1,2,14.0008964538574,4.99133737372202,34.850001335144,0.0437396178074428,0.00678621669889168,1,6.29788649559798E-8,,,,,,,,,,,,,,,,,,,,,4.99996280670166,5.00012588500977,839.895446777344,839.895446777344,54.7812163988135,5.79932284019731,2.73748755455017,28,1,0,0,1,0.32318115234375,28.3479976654053,1,1,1,4.99996280670166,0,5.00004434585571,,,,,,,,,,,,,,,,,,,,,,,,,,,,,,,,,
,3856362356.8395,4.99999165534973,749.942932128906,3.54725808611435E-5,1.25625761299022E-8,1,2,14.0008964538574,4.99130874605099,34.850001335144,0.0427870202362148,0.00664796374441069,1,6.93351397741118E-8,,,,,,,,,,,,,,,,,,,,,4.99996519088745,5.00001811981201,749.942932128906,749.942932128906,54.6706159633423,5.80063745527806,2.73353219032288,28,1,0,0,1,0.324172973632812,28.3479976654053,1,1,1,5.00001811981201,0,4.99999165534973,,,,,,,,,,,,,,,,,,,,,,,,,,,,,,,,,
,3856362391.32597,4.99963235855103,659.965942382813,3.46996384612656E-5,1.12911936593924E-8,1,2,14.0008964538574,4.99127331581785,34.8600000143051,0.0418511828406872,0.00652324466925036,1,8.45693493143432E-8,,,,,,,,,,,,,,,,,,,,,4.99954175949097,4.99972295761108,659.965942382813,659.965942382813,54.7706644138039,5.8012915438824,2.73150992393494,28,1,0,0,1,0.323638916015625,28.3479976654053,1,1,1,4.99972295761108,0,4.99963235855103,,,,,,,,,,,,,,,,,,,,,,,,,,,,,,,,,
,3856362421.51491,4.99969530105591,569.940002441406,3.3876900628603E-5,1.54830886348575E-8,1,2,14.0008964538574,4.99106885940481,34.8600000143051,0.0408542859375641,0.00638289469560715,1,9.47342782154077E-8,,,,,,,,,,,,,,,,,,,,,4.99958992004395,4.99980068206787,569.940002441406,569.940002441406,54.5158535165346,5.80239727700849,2.72389602661133,28,1,0,0,1,0.327072143554687,27.8592376708984,1,1,1,4.99958992004395,0,4.99969530105591,,,,,,,,,,,,,,,,,,,,,,,,,,,,,,,,,
,3856362453.0492,4.99993586540222,479.92626953125,3.3020062047066E-5,1.4704367100967E-8,1,2,14.0008964538574,4.99101977177693,34.850001335144,0.0398196018953723,0.00622671766001717,1,9.67720477355544E-8,,,,,,,,,,,,,,,,,,,,,4.99985980987549,5.00001192092895,479.92626953125,479.92626953125,54.7308013593231,5.80134585363268,2.72649478912354,28,1,0,0,1,0.319061279296875,28.8367557525635,1,1,1,4.99985980987549,0,4.99993586540222,,,,,,,,,,,,,,,,,,,,,,,,,,,,,,,,,
,3856362483.46952,4.99985337257385,389.998229980469,3.21347628257198E-5,1.29029991901915E-8,1,2,14.0008964538574,4.99094726780131,34.850001335144,0.0387480900209655,0.00608001088813969,1,1.11054127718728E-7,,,,,,,,,,,,,,,,,,,,,4.99982357025146,4.99988317489624,389.998229980469,389.998229980469,54.6956280759577,5.80322621724041,2.71508955955505,28,1,0,0,1,0.319061279296875,28.3479976654053,1,1,1,4.99988317489624,0,4.99985337257385,,,,,,,,,,,,,,,,,,,,,,,,,,,,,,,,,
,3856362515.88325,4.99989986419678,299.678466796875,3.11739256730319E-5,1.42656020523218E-8,1,2,14.0008964538574,4.99091436031156,34.850001335144,0.0375879056273772,0.00590638014339268,1,1.14544985534266E-7,,,,,,,,,,,,,,,,,,,,,4.9998927116394,4.99990701675415,299.678466796875,299.678466796875,54.7112606463423,5.80248672522942,2.7190101146698,28,1,0,0,1,0.323562622070313,29.3255138397217,1,1,1,4.99990701675415,0,4.99989986419678,,,,,,,,,,,,,,,,,,,,,,,,,,,,,,,,,
,3856362547.76494,5.00007581710815,209.554595947266,3.02094091723173E-5,1.20031514689997E-8,1,2,14.0008964538574,4.99098741644304,34.850001335144,0.0364285099506884,0.00570535357812306,1,9.57485741240866E-8,,,,,,,,,,,,,,,,,,,,,5.00003814697266,5.00011348724365,209.554595947266,209.554595947266,54.7718368565827,5.80218484969051,2.70986938476562,28,1,0,0,1,0.320892333984375,29.3255138397217,1,1,1,5.00003814697266,0,5.00007581710815,,,,,,,,,,,,,,,,,,,,,,,,,,,,,,,,,
,3856362579.97444,4.99983501434326,120.422271728516,2.92825290493323E-5,1.33174863779544E-8,1,2,14.0008964538574,4.99087335801667,34.850001335144,0.035303943662404,0.00556757405637135,1,1.2385162835555E-7,,,,,,,,,,,,,,,,,,,,,4.99977397918701,4.99989604949951,120.422271728516,120.422271728516,54.7515145150827,5.8031068021864,2.70585060119629,28,1,0,0,1,0.320281982421875,28.8367557525635,1,1,1,4.99977397918701,0,4.99983501434326,,,,,,,,,,,,,,,,,,,,,,,,,,,,,,,,,
,3856362613.71883,4.99984765052795,29.8331890106201,2.82718279718316E-5,1.28274731504437E-8,1,2,14.0008964538574,4.99074742522451,34.850001335144,0.0340876039795494,0.00535306717611944,1,1.01216418824226E-7,,,,,,,,,,,,,,,,,,,,,4.99981451034546,4.99988079071045,29.8331890106201,29.8331890106201,54.7843429128904,5.80279565480508,2.70343399047852,28,1,0,0,1,0.319976806640625,28.3479976654053,1,1,1,4.99988079071045,0,4.99984765052795,,,,,,,,,,,,,,,,,,,,,,,,,,,,,,,,,
,3856362645.36647,4.99987149238586,-59.752067565918,2.73532670961988E-5,1.53450823005253E-8,1,2,14.0008964538574,4.99087999847664,34.8600000143051,0.0329840912233395,0.0051612203824926,1,8.2911132118566E-8,,,,,,,,,,,,,,,,,,,,,4.99986457824707,4.99987840652466,-59.752067565918,-59.752067565918,54.7667562712077,5.80228677301717,2.7085919380188,28,1,0,0,1,0.323867797851562,29.3255138397217,1,1,1,4.99986457824707,0,4.99987149238586,,,,,,,,,,,,,,,,,,,,,,,,,,,,,,,,,
,3856362677.32871,4.99998164176941,-149.729064941406,2.6395426046793E-5,1.67638076131658E-8,1,2,14.0008964538574,4.99073865267333,34.850001335144,0.0318236015571536,0.00500774097552638,1,1.02762570051107E-7,,,,,,,,,,,,,,,,,,,,,4.99990940093994,5.00005388259888,-149.729064941406,-149.729064941406,54.6784322485346,5.80321238617436,2.70483207702637,28,1,0,0,1,0.321426391601562,28.8367557525635,1,1,1,5.00005388259888,0,4.99998164176941,,,,,,,,,,,,,,,,,,,,,,,,,,,,,,,,,
,3856362710.27877,5.00004577636719,-239.632598876953,2.54321629840276E-5,1.79503547421619E-8,1,2,14.0008964538574,4.99085061044531,34.8600000143051,0.0306610279889189,0.00483935373770664,1,1.1079249236175E-7,,,,,,,,,,,,,,,,,,,,,5.00004434585571,5.00004720687866,-239.632598876953,-239.632598876953,54.8042744401308,5.80291943824202,2.69833493232727,28,1,0,0,1,0.328826904296875,29.8142719268799,1,1,1,5.00004720687866,0,5.00004577636719,,,,,,,,,,,,,,,,,,,,,,,,,,,,,,,,,
,3856362744.95266,4.99992203712463,-329.670806884766,2.44659461984552E-5,2.04107437180082E-8,1,2,14.0008964538574,4.99063459120514,34.850001335144,0.0295006054501984,0.00461455925358098,1,7.28810357085181E-8,,,,,,,,,,,,,,,,,,,,,4.99979782104492,5.00004625320435,-329.670806884766,-329.670806884766,54.8820464777943,5.80385586658383,2.69511723518372,28,1,0,0,1,0.326461791992188,28.8367557525635,1,1,1,4.99979782104492,0,4.99992203712463,,,,,,,,,,,,,,,,,,,,,,,,,,,,,,,,,
,3856362779.40071,5.00006985664368,-420.541442871094,2.34791878722652E-5,1.87047677347042E-8,1,2,14.0008964538574,4.99063452055893,34.850001335144,0.0283054223665348,0.00446343702471198,1,9.8948380963403E-8,,,,,,,,,,,,,,,,,,,,,4.99992275238037,5.00021696090698,-420.541442871094,-420.541442871094,54.7143871604192,5.80444335319655,2.69399738311768,28,1,0,0,1,0.326690673828125,28.8367557525635,1,1,1,4.99992275238037,0,5.00006985664368,,,,,,,,,,,,,,,,,,,,,,,,,,,,,,,,,
,3856362813.81934,5.0000593662262,-510.371551513672,2.24110207803239E-5,2.17521809261258E-8,1,2,14.0008964538574,4.99059542296298,34.850001335144,0.0270162833007038,0.00426756730290334,1,1.00446475727365E-7,,,,,,,,,,,,,,,,,,,,,5.0000114440918,5.0001072883606,-510.371551513672,-510.371551513672,54.7304105450635,5.80538660528482,2.69773459434509,28,1,0,0,1,0.327911376953125,29.3255138397217,1,1,1,5.0000114440918,0,5.0000593662262,,,,,,,,,,,,,,,,,,,,,,,,,,,,,,,,,
,3856362848.30148,5.00001907348633,-600.360778808594,2.1381365256843E-5,2.2649713511128E-8,1,2,14.0008964538574,4.990751770383,34.8600000143051,0.025762527517679,0.00416064523037145,1,1.6958088190456E-7,,,,,,,,,,,,,,,,,,,,,5.0000171661377,5.00002098083496,-600.360778808594,-600.360778808594,54.7620665000923,5.80328649586867,2.68980574607849,28,1,0,0,1,0.325241088867188,28.8367557525635,1,1,1,5.0000171661377,0,5.00001907348633,,,,,,,,,,,,,,,,,,,,,,,,,,,,,,,,,
,3856362883.02668,5.00007295608521,-690.423461914062,2.03213102451743E-5,2.36237713070642E-8,1,2,14.0008964538574,4.99048598037713,34.850001335144,0.0244958056619502,0.00387342324401141,1,9.43159625193827E-8,,,,,,,,,,,,,,,,,,,,,4.99999141693115,5.00015449523926,-690.423461914062,-690.423461914062,54.8085733969866,5.803852515509,2.67922949790955,28,1,0,0,1,0.327224731445313,28.8367557525635,1,1,1,5.00015449523926,0,5.00007295608521,,,,,,,,,,,,,,,,,,,,,,,,,,,,,,,,,
,3856362916.91949,4.99971318244934,-780.36376953125,1.9125829793408E-5,2.58069265409782E-8,1,2,14.0008964538574,4.99060775202709,34.850001335144,0.0230378344421981,0.00376106487242706,1,1.84418668897719E-7,,,,,,,,,,,,,,,,,,,,,4.99963140487671,4.99979496002197,-780.36376953125,-780.36376953125,54.80505606865,5.80434321821105,2.67301869392395,28,1,0,0,1,0.323715209960937,29.3255138397217,1,1,1,4.99979496002197,0,4.99971318244934,,,,,,,,,,,,,,,,,,,,,,,,,,,,,,,,,
,3856362951.63621,4.99994325637817,-870.132568359375,1.77957370217829E-5,3.53392223733901E-8,1,2,14.0008964538574,4.99039700101597,34.850001335144,0.0214386617390811,0.0034716221582067,1,1.4865028156779E-7,,,,,,,,,,,,,,,,,,,,,4.99988174438477,5.00000476837158,-870.132568359375,-870.132568359375,54.7679287139866,5.80544144469531,2.67294859886169,28,1,0,0,1,0.319061279296875,28.8367557525635,1,1,1,5.00000476837158,0,4.99994325637817,,,,,,,,,,,,,,,,,,,,,,,,,,,,,,,,,
,3856362986.38076,4.99990558624268,-960.268737792969,1.55084845070852E-5,3.68930945877981E-8,1,2,14.0008964538574,4.99043906676391,34.850001335144,0.0186667051117285,0.00313438318095651,1,2.19844906135958E-7,,,,,,,,,,,,,,,,,,,,,4.99969863891602,5.00011253356934,-960.268737792969,-960.268737792969,54.6127754529192,5.80472512161839,2.67331671714783,28,1,0,0,1,0.32196044921875,29.3255138397217,1,1,1,4.99957942962646,0,4.99990558624268,,,,,,,,,,,,,,,,,,,,,,,,,,,,,,,,,
,3856363020.26213,4.99993252754211,-1049.69494628906,6.82779292048052E-6,7.01411515366367E-8,1,2,14.0008964538574,4.99043531521476,34.850001335144,0.00820185205427468,0.00148672079310917,1,1.85304724233244E-7,,,,,,,,,,,,,,,,,,,,,4.99985504150391,5.00001001358032,-1049.69494628906,-1049.69494628906,54.6760873629769,5.80495098967352,2.67686080932617,28,1,0,0,1,0.321121215820313,27.8592376708984,1,1,1,4.99985504150391,0,4.99993252754211,,,,,,,,,,,,,,,,,,,,,,,,,,,,,,,,,
,3856363052.84368,4.99992108345032,-1139.72082519531,-2.25656808481678E-5,1.10675274106722E-7,1,2,14.0008964538574,4.990379744644,34.850001335144,-0.0272917697096793,-0.0037054491163707,1,3.89065871747685E-7,,,,,,,,,,,,,,,,,,,,,4.99990177154541,4.99994039535522,-1139.72082519531,-1139.72082519531,54.7569859147173,5.80517062224014,2.67256498336792,28,1,0,0,1,0.323562622070313,27.8592376708984,1,1,1,4.99994039535522,0,4.99992108345032,,,,,,,,,,,,,,,,,,,,,,,,,,,,,,,,,
,3856363087.63249,4.99992537498474,-1229.73449707031,-3.61706024609043E-5,2.95724703543398E-8,1,2,14.0008964538574,4.99039519964224,34.850001335144,-0.0436789583626123,-0.00637828275458109,1,2.59879670413297E-7,,,,,,,,,,,,,,,,,,,,,4.99991846084595,4.99993228912354,-1229.73449707031,-1229.73449707031,54.7229850741308,5.80475087140647,2.67299699783325,28,1,0,0,1,0.320663452148438,28.8367557525635,1,1,1,4.99993228912354,0,4.99992537498474,,,,,,,,,,,,,,,,,,,,,,,,,,,,,,,,,
,3856363122.18415,4.99987769126892,-1319.73608398438,-3.94361875727489E-5,1.79077107619181E-8,1,2,14.0008964538574,4.9903718333985,34.850001335144,-0.0476082936888192,-0.00704415193024397,1,2.08676566613467E-7,,,,,,,,,,,,,,,,,,,,,4.99984931945801,4.99990606307983,-1319.73608398438,-1319.73608398438,54.88634543465,5.80595508047992,2.67184710502625,28,1,0,0,1,0.325698852539063,28.3479976654053,1,1,1,4.99990606307983,0,4.99987769126892,,,,,,,,,,,,,,,,,,,,,,,,,,,,,,,,,
,3856363156.63114,4.99996399879456,-1409.70080566406,-4.08559270246204E-5,2.22149976534591E-8,1,2,14.0008964538574,4.99030974425565,34.850001335144,-0.0493211039740498,-0.00729940578970342,1,2.14709367776335E-7,,,,,,,,,,,,,,,,,,,,,4.99985551834106,5.00007247924805,-1409.70080566406,-1409.70080566406,54.8156080536596,5.80625043731864,2.67194294929504,28,1,0,0,1,0.321807861328125,28.8367557525635,1,1,1,4.99985551834106,0,4.99996399879456,,,,,,,,,,,,,,,,,,,,,,,,,,,,,,,,,
,3856363191.08677,4.99993515014648,-1499.8369140625,-4.18118886256871E-5,1.85309881582588E-8,1,2,14.0008964538574,4.99039095450778,34.850001335144,-0.0504732045113891,-0.00749046432915241,1,2.03074748281282E-7,,,,,,,,,,,,,,,,,,,,,4.99987649917603,4.99999380111694,-1499.8369140625,-1499.8369140625,54.8226427103327,5.80546226015569,2.67364692687988,28,1,0,0,1,0.324630737304687,28.3479976654053,1,1,1,4.99987649917603,0,4.99993515014648,,,,,,,,,,,,,,,,,,,,,,,,,,,,,,,,,
,3856363234.10546,4.99987888336182,-2099.68359375,-4.65237285442166E-5,1.39723615053572E-8,1,2,14.0008964538574,4.99019265814638,34.850001335144,-0.0561141172845586,-0.00862008055209534,1,-1.11260950432868E-8,,,,,,,,,,,,,,,,,,,,,4.99981594085693,4.9999418258667,-2099.68359375,-2099.68359375,54.8906443915058,5.80699248307425,2.66862320899963,28,1,0,0,1,0.321731567382812,27.3704795837402,1,1,1,4.9999418258667,0,4.99987888336182,,,,,,,,,,,,,,,,,,,,,,,,,,,,,,,,,
,3856363269.91881,4.99985504150391,-2999.79614257812,-5.31977764223678E-5,1.37532917187157E-8,1,2,14.0008964538574,4.99023147395715,34.8600000143051,-0.0641644163888594,-0.0098583027804848,1,-1.39854852618273E-8,,,,,,,,,,,,,,,,,,,,,4.99969959259033,5.00001049041748,-2999.79614257812,-2999.79614257812,54.7073525037462,5.80612582377951,2.66399765014648,28,1,0,0,1,0.325775146484375,28.3479976654053,1,1,1,4.99969959259033,0,4.99985504150391,,,,,,,,,,,,,,,,,,,,,,,,,,,,,,,,,
,3856363303.62648,4.99997520446777,-2099.548828125,-4.63835817321105E-5,1.13793755396615E-8,1,2,14.0008964538574,4.99019067046541,34.850001335144,-0.0559661032929362,-0.00845683603256424,1,1.02715026366367E-7,,,,,,,,,,,,,,,,,,,,,4.99987268447876,5.00007772445679,-2099.548828125,-2099.548828125,54.7358819446981,5.80601043210408,2.67108082771301,28,1,0,0,1,0.320587158203125,29.3255138397217,1,1,1,4.99987268447876,0,4.99997520446777,,,,,,,,,,,,,,,,,,,,,,,,,,,,,,,,,
,3856363347.3226,4.99969625473022,-1499.64111328125,-4.17640785570981E-5,9.98988210950083E-9,1,2,14.0008964538574,4.9900895827114,34.850001335144,-0.0503788614568903,-0.00769230954237605,1,2.78703113326727E-8,,,,,,,,,,,,,,,,,,,,,4.99969625473022,4.99969625473022,-1499.64111328125,-1499.64111328125,54.9613817724962,5.80661067400891,2.66683959960938,28,1,0,0,1,0.322265625,29.3255138397217,1,1,1,4.99969625473022,0,4.99969625473022,,,,,,,,,,,,,,,,,,,,,,,,,,,,,,,,,
,3856363382.05,4.99997615814209,-1409.65173339844,-4.10821725143126E-5,1.25292096746688E-8,1,2,14.0008964538574,4.99006787732929,34.850001335144,-0.0495429398746509,-0.00765178875772707,1,-4.31585590685822E-8,,,,,,,,,,,,,,,,,,,,,4.99997568130493,4.99997663497925,-1409.65173339844,-1409.65173339844,54.7761358134385,5.8067034329397,2.6643340587616,28,1,0,0,1,0.324554443359375,29.3255138397217,1,1,1,4.99997568130493,0,4.99997615814209,,,,,,,,,,,,,,,,,,,,,,,,,,,,,,,,,
,3856363416.14777,5.00018715858459,-1319.650390625,-4.03547494278809E-5,1.09675909122604E-8,1,2,14.0008964538574,4.99003906225397,34.850001335144,-0.0486669154694287,-0.00750579023498616,1,-3.37294146806795E-8,,,,,,,,,,,,,,,,,,,,,5.00008201599121,5.00029230117798,-1319.650390625,-1319.650390625,54.6229366236692,5.8071298770994,2.66910243034363,28,1,0,0,1,0.321197509765625,28.8367557525635,1,1,1,5.00029230117798,0,5.00018715858459,,,,,,,,,,,,,,,,,,,,,,,,,,,,,,,,,
,3856363450.33505,5.0000855922699,-1229.68566894531,-3.96083435204624E-5,1.20523850505681E-8,1,2,14.0008964538574,4.98995356535328,34.850001335144,-0.0477642963057267,-0.00737542507528822,1,-4.02686451201893E-8,,,,,,,,,,,,,,,,,,,,,4.99995803833008,5.00021314620972,-1229.68566894531,-1229.68566894531,54.8159988679193,5.80694698054707,2.66118168830872,28,1,0,0,1,0.325546264648438,29.3255138397217,1,1,1,5.00021314620972,0,5.0000855922699,,,,,,,,,,,,,,,,,,,,,,,,,,,,,,,,,
,3856363484.78115,5.00012969970703,-1139.64733886719,-3.88986684233752E-5,1.25303971242533E-8,1,2,14.0008964538574,4.99030017386622,34.850001335144,-0.046914515653531,-0.00723441769144991,1,-3.16184337374666E-8,,,,,,,,,,,,,,,,,,,,,5.00010585784912,5.00015354156494,-1139.64733886719,-1139.64733886719,54.864069021852,5.80663100010867,2.66377115249634,28,1,0,0,1,0.32257080078125,29.3255138397217,1,1,1,5.00010585784912,0,5.00012969970703,,,,,,,,,,,,,,,,,,,,,,,,,,,,,,,,,
,3856363517.26124,5.00012898445129,-1049.64587402344,-3.81357561790761E-5,1.27611973587171E-8,1,2,14.0008964538574,4.99042023164798,34.850001335144,-0.045992706717349,-0.00711384247528164,1,-4.84681951691946E-8,,,,,,,,,,,,,,,,,,,,,5.00010871887207,5.00014925003052,-1049.64587402344,-1049.64587402344,54.7558134719385,5.80568327977257,2.6688129901886,28,1,0,0,1,0.320663452148438,29.3255138397217,1,1,1,5.00010871887207,0,5.00012898445129,,,,,,,,,,,,,,,,,,,,,,,,,,,,,,,,,
,3856363551.56038,5.0002236366272,-959.570983886719,-3.73983487532689E-5,1.18142863254761E-8,1,2,14.0008964538574,4.99028969547087,34.850001335144,-0.0451001446502893,-0.00698632324604411,1,-5.60635510616793E-8,,,,,,,,,,,,,,,,,,,,,5.00020170211792,5.00024557113647,-959.570983886719,-959.570983886719,54.7061800609673,5.80598906344071,2.66106534004211,28,1,0,0,1,0.320968627929687,29.3255138397217,1,1,1,5.00024557113647,0,5.0002236366272,,,,,,,,,,,,,,,,,,,,,,,,,,,,,,,,,
,3856363586.75976,4.99984192848206,-869.777587890625,-3.66336482165773E-5,1.26722724217639E-8,1,2,14.0008964538574,4.99023673894131,34.850001335144,-0.0441782276312942,-0.00683735982481469,1,-4.993514054616E-8,,,,,,,,,,,,,,,,,,,,,4.99941968917847,5.00026416778564,-869.777587890625,-869.777587890625,54.7984122262366,5.80574615597065,2.66422367095947,28,1,0,0,1,0.32440185546875,28.8367557525635,1,1,1,4.99941968917847,0,4.99984192848206,,,,,,,,,,,,,,,,,,,,,,,,,,,,,,,,,
,3856363620.26613,5.00006246566772,-779.751647949219,-3.58719418302492E-5,1.36859171063725E-8,1,2,14.0008964538574,4.9903092608006,34.850001335144,-0.0432512617517669,-0.00675576104023577,1,-9.89962688768057E-8,,,,,,,,,,,,,,,,,,,,,4.99991035461426,5.00021457672119,-779.751647949219,-779.751647949219,54.7706644138039,5.80549227691662,2.65787100791931,28,1,0,0,1,0.324249267578125,29.8142719268799,1,1,1,4.99991035461426,0,5.00006246566772,,,,,,,,,,,,,,,,,,,,,,,,,,,,,,,,,
,3856363652.82542,4.99992179870605,-689.68896484375,-3.50659837569033E-5,1.52035709308611E-8,1,2,14.0008964538574,4.99014465453746,34.8600000143051,-0.0422795954465655,-0.00659037217886524,1,-8.57470997240971E-8,,,,,,,,,,,,,,,,,,,,,4.99974346160889,5.00010013580322,-689.68896484375,-689.68896484375,54.6459946649865,5.80606415544134,2.66487550735474,28,1,0,0,1,0.324630737304687,28.8367557525635,1,1,1,4.99974346160889,0,4.99992179870605,,,,,,,,,,,,,,,,,,,,,,,,,,,,,,,,,
,3856363685.46653,4.9999692440033,-599.846618652344,-3.42536807597543E-5,1.26629640128281E-8,1,2,14.0008964538574,4.99018540756866,34.850001335144,-0.0413008639223492,-0.00643645878718103,1,-8.26654945791126E-8,,,,,,,,,,,,,,,,,,,,,4.99974870681763,5.00018978118897,-599.846618652344,-599.846618652344,54.8761842639,5.80660678731404,2.66518115997314,28,1,0,0,1,0.324859619140625,28.8367557525635,1,1,1,5.00018978118897,0,4.9999692440033,,,,,,,,,,,,,,,,,,,,,,,,,,,,,,,,,
,3856363717.75238,4.99970722198486,-509.845153808594,-3.34158908916495E-5,1.22165361874319E-8,1,2,14.0008964538574,4.99009426676155,34.850001335144,-0.0402830208191879,-0.00632230037089054,1,-1.16648670877535E-7,,,,,,,,,,,,,,,,,,,,,4.99953079223633,4.9998836517334,-509.845153808594,-509.845153808594,54.7210310028327,5.80594894440032,2.65859079360962,28,1,0,0,1,0.31951904296875,28.8367557525635,1,1,1,4.99953079223633,0,4.99970722198486,,,,,,,,,,,,,,,,,,,,,,,,,,,,,,,,,
,3856363749.34654,5.00018763542175,-419.8681640625,-3.25165064372456E-5,1.377483223118E-8,1,2,14.0008964538574,4.99013350247527,34.850001335144,-0.0392011188596704,-0.00613995256319927,1,-1.03351595998279E-7,,,,,,,,,,,,,,,,,,,,,5.00016260147095,5.00021266937256,-419.8681640625,-419.8681640625,54.8140447966212,5.8075107574667,2.65841937065125,28,1,0,0,1,0.321121215820313,28.8367557525635,1,1,1,5.00016260147095,0,5.00018763542175,,,,,,,,,,,,,,,,,,,,,,,,,,,,,,,,,
,3856363780.17951,4.99989748001099,-329.854431152344,-3.15978237490514E-5,1.54862997588308E-8,1,2,14.0008964538574,4.99016809233195,34.850001335144,-0.0380898685916004,-0.00599312881564253,1,-1.22475911211049E-7,,,,,,,,,,,,,,,,,,,,,4.99985027313232,4.99994468688965,-329.854431152344,-329.854431152344,54.7921591980827,5.80654583323921,2.65806818008423,28,1,0,0,1,0.324935913085937,28.8367557525635,1,1,1,4.99994468688965,0,4.99989748001099,,,,,,,,,,,,,,,,,,,,,,,,,,,,,,,,,
,3856363811.40565,5.0001814365387,-239.963134765625,-3.06537436110108E-5,1.59924675632598E-8,1,2,14.0008964538574,4.99021415444305,34.850001335144,-0.0369523404855266,-0.00581385398657631,1,-1.1857849494169E-7,,,,,,,,,,,,,,,,,,,,,5.0000958442688,5.00026702880859,-239.963134765625,-239.963134765625,54.7788715132558,5.80693023637994,2.65601229667664,28,1,0,0,1,0.323104858398438,28.8367557525635,1,1,1,5.00026702880859,0,5.0001814365387,,,,,,,,,,,,,,,,,,,,,,,,,,,,,,,,,
,3856363842.02205,4.99987101554871,-150.169769287109,-2.96249793500213E-5,1.70413751537865E-8,1,2,14.0008964538574,4.99006335459734,34.8600000143051,-0.0357054606047984,-0.00565252859048718,1,-1.4281275066366E-7,,,,,,,,,,,,,,,,,,,,,4.99963569641113,5.00010633468628,-150.169769287109,-150.169769287109,54.6389600083135,5.80700451476564,2.66034412384033,28,1,0,0,1,0.3228759765625,28.3479976654053,1,1,1,4.99963569641113,0,4.99987101554871,,,,,,,,,,,,,,,,,,,,,,,,,,,,,,,,,
,3856363874.37872,5.00030612945557,-60.0825958251953,-2.86809312183306E-5,1.54309262686393E-8,1,2,14.0008964538574,4.99013038035892,34.850001335144,-0.0345661307998026,-0.00548663412676814,1,-1.49976354302484E-7,,,,,,,,,,,,,,,,,,,,,4.99989175796509,5.00072050094604,-60.0825958251953,-60.0825958251953,54.6620180496308,5.8064006936749,2.66315174102783,28,1,0,0,1,0.325393676757812,28.3479976654053,1,1,1,4.99989175796509,0,5.00030612945557,,,,,,,,,,,,,,,,,,,,,,,,,,,,,,,,,
,3856363906.59132,5.00008630752563,29.9311237335205,-2.77617000390441E-5,1.39358289103741E-8,1,2,14.0008964538574,4.99022433790494,34.850001335144,-0.0334580335558013,-0.00531826517767913,1,-1.51254102241631E-7,,,,,,,,,,,,,,,,,,,,,5.00004625320435,5.00012636184692,29.9311237335205,29.9311237335205,54.6459946649865,5.80624008954607,2.66010308265686,28,1,0,0,1,0.3228759765625,28.8367557525635,1,1,1,5.00012636184692,0,5.00008630752563,,,,,,,,,,,,,,,,,,,,,,,,,,,,,,,,,
,3856363937.78095,4.99977707862854,119.871398925781,-2.67726172778221E-5,1.86466055282339E-8,1,2,14.0008964538574,4.99013859037377,34.850001335144,-0.0322714611437503,-0.00508802503159586,1,-1.12171920234484E-7,,,,,,,,,,,,,,,,,,,,,4.9996919631958,4.99986219406128,119.871398925781,119.871398925781,54.6385691940539,5.80770637036798,2.66049885749817,28,1,0,0,1,0.321273803710937,28.8367557525635,1,1,1,4.9996919631958,0,4.99977707862854,,,,,,,,,,,,,,,,,,,,,,,,,,,,,,,,,
,3856363970.88602,5.00029897689819,209.885116577148,-2.58103366281487E-5,2.19890508243191E-8,1,2,14.0008964538574,4.99021731034384,34.850001335144,-0.0311083434696755,-0.00493055724598347,1,-1.29116386738004E-7,,,,,,,,,,,,,,,,,,,,,4.99992084503174,5.00067710876465,209.885116577148,209.885116577148,54.769491971025,5.80652895234389,2.6616370677948,28,1,0,0,1,0.324249267578125,29.8142719268799,1,1,1,4.99992084503174,0,5.00029897689819,,,,,,,,,,,,,,,,,,,,,,,,,,,,,,,,,
,3856364003.02333,5.00010824203491,299.996765136719,-2.48787253846372E-5,1.79322022328573E-8,1,2,14.0008964538574,4.99034374035377,34.850001335144,-0.0299832256013981,-0.00477454307871045,1,-1.42514928930308E-7,,,,,,,,,,,,,,,,,,,,,5.00004482269287,5.00017166137695,299.996765136719,299.996765136719,54.7421349728519,5.80559716774503,2.65462183952332,28,1,0,0,1,0.321044921875,28.3479976654053,1,1,1,5.00017166137695,0,5.00010824203491,,,,,,,,,,,,,,,,,,,,,,,,,,,,,,,,,
,3856364037.02831,5.00002074241638,389.679962158203,-2.38158224060579E-5,2.19195749297542E-8,1,2,14.0008964538574,4.99024249560218,34.850001335144,-0.0287088317608293,-0.00452214380623734,1,-9.63956244079402E-8,,,,,,,,,,,,,,,,,,,,,4.9998574256897,5.00018405914307,389.679962158203,389.679962158203,54.7507328865635,5.80601734029157,2.64489150047302,28,1,0,0,1,0.318603515625,29.3255138397217,1,1,1,4.9998574256897,0,5.00002074241638,,,,,,,,,,,,,,,,,,,,,,,,,,,,,,,,,
,3856364072.66133,4.99991846084595,480.379211425781,-2.2772437843362E-5,2.47915677512989E-8,1,2,14.0008964538574,4.99020271681549,34.850001335144,-0.027439649945097,-0.00439651718854729,1,-1.52311794488517E-7,,,,,,,,,,,,,,,,,,,,,4.99987983703613,4.99995708465576,480.379211425781,480.379211425781,54.6710067776019,5.80650471818042,2.64412713050842,28,1,0,0,1,0.32562255859375,28.8367557525635,1,1,1,4.99995708465576,0,4.99991846084595,,,,,,,,,,,,,,,,,,,,,,,,,,,,,,,,,
,3856364105.07287,4.99978709220886,569.842041015625,-2.17709367612611E-5,2.34460633469629E-8,1,2,14.0008964538574,4.99026276959427,34.850001335144,-0.0262265675881249,-0.00424734619363013,1,-1.82183401871891E-7,,,,,,,,,,,,,,,,,,,,,4.99977922439575,4.99979496002197,569.842041015625,569.842041015625,54.7304105450635,5.80619590792438,2.64232969284058,28,1,0,0,1,0.328445434570313,30.7917900085449,1,1,1,4.99977922439575,0,4.99978709220886,,,,,,,,,,,,,,,,,,,,,,,,,,,,,,,,,
,3856364137.00816,5.00016140937805,659.708862304687,-2.0768369622215E-5,2.38572004963858E-8,1,2,14.0008964538574,4.99019652767161,34.850001335144,-0.0250151536597068,-0.0040725224122204,1,-1.91075324476015E-7,,,,,,,,,,,,,,,,,,,,,5.00005722045898,5.00026559829712,659.708862304687,659.708862304687,54.7679287139866,5.8064011942111,2.64616942405701,28,1,0,0,1,0.324249267578125,25.4154453277588,1,1,1,5.00026559829712,0,5.00016140937805,,,,,,,,,,,,,,,,,,,,,,,,,,,,,,,,,
,3856364169.37214,5.00009274482727,749.808288574219,-1.96860741579986E-5,2.71058800082855E-8,1,2,14.0008964538574,4.99028542187359,34.850001335144,-0.0237179866503392,-0.00382225521788308,1,-1.49503813778777E-7,,,,,,,,,,,,,,,,,,,,,4.99999332427978,5.00019216537476,749.808288574219,749.808288574219,54.8292865527462,5.80604770711158,2.64329051971436,28,1,0,0,1,0.320968627929687,28.8367557525635,1,1,1,4.99999332427978,0,5.00009274482727,,,,,,,,,,,,,,,,,,,,,,,,,,,,,,,,,
,3856364203.80899,4.99979138374329,839.773071289063,-1.84558953205686E-5,2.87636769527309E-8,1,2,14.0008964538574,4.99017825352694,34.850001335144,-0.0222234239679714,-0.00365998556722823,1,-2.03742303712992E-7,,,,,,,,,,,,,,,,,,,,,4.99978017807007,4.9998025894165,839.773071289063,839.773071289063,54.7757449991789,5.8068813550011,2.65187406539917,28,1,0,0,1,0.321502685546875,29.3255138397217,1,1,1,4.9998025894165,0,4.99979138374329,,,,,,,,,,,,,,,,,,,,,,,,,,,,,,,,,
,3856364236.04126,5.00000143051147,929.798950195313,-1.67425605876839E-5,4.51812685822051E-8,1,2,14.0008964538574,4.99013500161184,34.850001335144,-0.0201495676787187,-0.00338877989804173,1,-2.41707344608739E-7,,,,,,,,,,,,,,,,,,,,,4.99984121322632,5.00016164779663,929.798950195313,929.798950195313,54.7819980273327,5.80697657253962,2.65211915969849,28,1,0,0,1,0.3302001953125,29.3255138397217,1,1,1,5.00016164779663,0,5.00000143051147,,,,,,,,,,,,,,,,,,,,,,,,,,,,,,,,,
,3856364269.58968,5.00004410743713,1019.62915039062,-1.18464411013885E-5,8.77868596134403E-8,1,2,14.0008964538574,4.99030768598527,34.850001335144,-0.0142715911403455,-0.00230803432641247,1,-9.65247980450482E-8,,,,,,,,,,,,,,,,,,,,,4.99995899200439,5.00012922286987,1019.62915039062,1019.62915039062,54.7265024024673,5.8061262714625,2.65136361122131,28,1,0,0,1,0.321426391601562,29.3255138397217,1,1,1,4.99995899200439,0,5.00004410743713,,,,,,,,,,,,,,,,,,,,,,,,,,,,,,,,,
,3856364301.82492,5.00002527236938,1109.66723632812,1.01401012181694E-5,1.78698217504479E-7,1,2,14.0008964538574,4.99024689767473,34.850001335144,0.0123247201491605,0.00126492237567318,1,-5.06527710638494E-7,,,,,,,,,,,,,,,,,,,,,5.00001859664917,5.0000319480896,1109.66723632812,1109.66723632812,54.7253299596885,5.80732605829593,2.64626002311707,28,1,0,0,1,0.32257080078125,29.3255138397217,1,1,1,5.00001859664917,0,5.00002527236938,,,,,,,,,,,,,,,,,,,,,,,,,,,,,,,,,
,3856364342.30031,5.00016665458679,1199.57092285156,3.35507676198747E-5,3.58157279122782E-8,1,2,14.0008964538574,4.99011076747073,34.850001335144,0.0405050325296717,0.00596166393835604,1,-2.03058368783299E-7,,,,,,,,,,,,,,,,,,,,,4.99999189376831,5.00034141540527,1199.57092285156,1199.57092285156,54.7605032430539,5.8068920546836,2.64723348617554,28,1,0,0,1,0.322036743164063,28.8367557525635,1,1,1,5.00034141540527,0,5.00016665458679,,,,,,,,,,,,,,,,,,,,,,,,,,,,,,,,,
,3856364374.56378,4.99985575675964,1289.572265625,3.86051517221693E-5,2.74040387452E-8,1,2,14.0008964538574,4.99013212306065,34.850001335144,0.0465954004499188,0.00693771993966809,1,-1.69066272600911E-7,,,,,,,,,,,,,,,,,,,,,4.99952507019043,5.00018644332886,1289.572265625,1289.572265625,54.7722276708423,5.80675980597302,2.65083718299866,28,1,0,0,1,0.320892333984375,29.8142719268799,1,1,1,4.99952507019043,0,4.99985575675964,,,,,,,,,,,,,,,,,,,,,,,,,,,,,,,,,
,3856364408.39567,4.99978804588318,1379.52478027344,4.04383146476687E-5,1.75598707970905E-8,1,2,14.0008964538574,4.99027820173726,34.850001335144,0.0488130925400564,0.00724715736037741,1,-1.93921804284472E-7,,,,,,,,,,,,,,,,,,,,,4.99973011016846,4.9998459815979,1379.52478027344,1379.52478027344,54.6713975918615,5.80761349512194,2.64645886421204,28,1,0,0,1,0.321426391601562,27.3704795837402,1,1,1,4.9998459815979,0,4.99978804588318,,,,,,,,,,,,,,,,,,,,,,,,,,,,,,,,,
,3856364441.76041,5.00006437301636,1469.77111816406,4.15037151930948E-5,1.82014243430465E-8,1,2,14.0008964538574,4.99014146815725,34.850001335144,0.0500940966711283,0.00745814897437924,1,-1.82166787299197E-7,,,,,,,,,,,,,,,,,,,,,4.99975204467773,5.00037670135498,1469.77111816406,1469.77111816406,54.7855153556693,5.8066243846707,2.64969348907471,28,1,0,0,1,0.325088500976562,29.3255138397217,1,1,1,4.99975204467773,0,5.00006437301636,,,,,,,,,,,,,,,,,,,,,,,,,,,,,,,,,
,3856364484.23633,4.99983382225037,1799.65002441406,4.42313317277999E-5,1.80347329046678E-8,1,2,14.0008964538574,4.99038335502193,34.850001335144,0.0533541157970749,0.00818210882922869,1,-7.52023890611524E-10,,,,,,,,,,,,,,,,,,,,,4.99972534179687,4.99994230270386,1799.65002441406,1799.65002441406,54.8382752807173,5.80687712523861,2.6502890586853,28,1,0,0,1,0.321426391601562,29.3255138397217,1,1,1,4.99972534179687,0,4.99983382225037,,,,,,,,,,,,,,,,,,,,,,,,,,,,,,,,,
,3856364520.01304,5.00010395050049,2699.5546875,5.09981152415218E-5,1.22461752269997E-8,1,2,14.0008964538574,4.99017797433569,34.8600000143051,0.0615142764914886,0.00942509759828263,1,-7.68000800153718E-9,,,,,,,,,,,,,,,,,,,,,4.99995040893555,5.00025749206543,2699.5546875,2699.5546875,54.8038836258712,5.80728272285941,2.64894032478333,28,1,0,0,1,0.327224731445313,28.3479976654053,1,1,1,4.9999942779541,0,5.00010395050049,,,,,,,,,,,,,,,,,,,,,,,,,,,,,,,,,
,3856364531.65662,4.99958729743958,2999.60034179687,5.31747684695796E-5,1.06791487731335E-8,1,2,14.0008964538574,4.99007136395394,34.850001335144,0.0641358862961459,0.00983989805762602,1,2.62213682286063E-9,,,,,,,,,,,,,,,,,,,,,4.99942779541016,4.99974679946899,2999.60034179687,2999.60034179687,54.7941132693808,5.80790870470074,2.65390253067017,28,1,0,0,1,0.322189331054687,28.8367557525635,1,1,1,4.99974679946899,0,4.99958729743958,,,,,,,,,,,,,,,,,,,,,,,,,,,,,,,,,